Workbook

Sheet BIO DATA
A1: NO+A:AJ | B1: 3 MTs | C1: PARALEL | D1: NIS | E1: NISN | F1: NAMA SISWA | G1: TGL MASUK | H1: TAHUN IJAZAH | I1: NO IJAZAH | J1: Anak Ke | K1: Jml Saudara | L1: Nomor Pendaftaran | M1: Jenis Kelamin | N1: TEMPAT LAHIR | O1: TANGGAL LAHIR | P1: TANGGAL LAHIR1 | Q1: TANGGAL LAHIR2 | R1: NIK ANAK | S1: Agama | T1: ALAMAT | U1: KODE POS | V1: DESA/KELURAHAN | W1: KECAMATAN | X1: Kabupaten/kota | Y1: Provinsi | Z1: Asal Sekolah | AA1: Alamat Sekolah | AB1: Prestasi | AC1: Nama Ayah | AD1: Agama Ayah | AE1: Pendidikan | AF1: Pekerjaan | AG1: Penghasilan | AH1: Telp | AI1: Email | AJ1: Nama Ibu | AK1: Agama Ibu | AL1: Pendidikan | AM1: Pekerjaan | AN1: Penghasilan | AO1: Telp | AP1: Email | AQ1: KK | AR1: NIK AYAH | AS1: TEMPAT LAHIR AYAH | AT1: TGL LAHIR AYAH | AV1: NIK IBU | AW1: TEMPAT LAHIR IBU | AX1: TGL LAHIR IBU | AZ1: Nama Wali | BA1: Agama Wali | BB1: Pendidikan | BC1: Pekerjaan | BD1: Alamat Wali | BE1: Penghasilan | BF1: Telp | BG1: Email | BH1: Nama WK | BI1: NBM WK | BJ1: Nama Direktur | BK1: NBM/NIP.
A2: 1 | B2: F | C2: A | D2: 11543 | E2: 3101049926 | F2: Ainurrofiq Syamsudin | G2: 17 Juli 2023 | J2: 1 | K2: 2 | M2: Laki-laki | N2: Baranusa | P2: 40330 | Q2: 1 Juni 2010 | S2: Islam | T2: Jl. Imam Bonjol No. 143 RT 002 RW 001 Adang Buom Teluk Mutiara Alor Nusa Tenggara Timur | V2: Adang Buom | W2: Teluk Mutiara | X2: Alor | Y2: Nusa Tenggara Timur | Z2: MTs Mu'allimin Muh Yogyakarta | AA2: Jalan Suroto 5 Padukuhan Jl. Gn. Bulu, Bandut Lor, Argorejo, Kec. Sedayu, Kabupaten Bantul, Daerah Istimewa Yogyakarta 55753 | AC2: Muhammad H. Sjamsuddin | AD2: Islam | AE2: S1 | AF2: PNS | AH2: 085238964122 | AJ2: Selfiah Harlina | AK2: Islam | AL2: SMA | AM2: Ibu Rumah Tangga | BA2: Islam | BH2: Mohammad Sanusi, S.H.I. | BI2: 786961 | BJ2: Dr. Mhd. Lailan Arqam, M.Pd. | BK2: - / 895 833
A3: 2 | B3: B | C3: A | D3: 11586 | E3: 0105875288 | F3: Elka Maulana Iskandar | G3: 17 Juli 2023 | J3: 1 | K3: 1 | M3: Laki-laki | N3: Kudus | P3: 40530 | Q3: 18 Desember 2010 | S3: Islam | T3: Bae RT 001 RW 001 Bae Kudus Jawa Tengah | V3: Bae | W3: Bae | X3: Kudus | Y3: Jawa Tengah | Z3: MTs Mu'allimin Muh Yogyakarta | AA3: Jalan Suroto 5 Padukuhan Jl. Gn. Bulu, Bandut Lor, Argorejo, Kec. Sedayu, Kabupaten Bantul, Daerah Istimewa Yogyakarta 55754 | AC3: Heri Iskandar | AD3: Islam | AE3: D-III | AF3: Wiraswasta | AJ3: Deka Ayu Khotima | AK3: Islam | AL3: S1 | AM3: Guru | AO3: 081328375021 | AQ3: 3319071204070044 | AR3: 3319070605820007 | AS3: Kudus | AT3: 30077 | AV3: 331907510830002 | AW3: Pati | AX3: 30539 | BA3: Islam | BH3: Mohammad Sanusi, S.H.I. | BI3: 786961 | BJ3: Dr. Mhd. Lailan Arqam, M.Pd. | BK3: - / 895 833
A4: 3 | B4: A | C4: A | D4: 11589 | E4: 3111141420 | F4: Fahma Akhsananda Hidayat | G4: 17 Juli 2023 | J4: 3 | K4: 2 | M4: Laki-laki | N4: Cilacap | P4: 40659 | Q4: 26 April 2011 | S4: Islam | T4: Jl. Hadiwisastro RT 004 RW 002 Pesawahan Binangun Cilacap Jawa Tengah 53281 | U4: 53281 | V4: Pesawahan | W4: Binangun | X4: Cilacap | Y4: Jawa Tengah | Z4: MTs Mu'allimin Muh Yogyakarta | AA4: Jalan Suroto 5 Padukuhan Jl. Gn. Bulu, Bandut Lor, Argorejo, Kec. Sedayu, Kabupaten Bantul, Daerah Istimewa Yogyakarta 55756 | AC4: Nur Hidayat, S.Ag. | AD4: Islam | AE4: S1 | AF4: Guru | AH4: 081329062822 | AJ4: Tarwiyah, S.Ag. | AK4: Islam | AL4: S1 | AM4: Guru | AQ4: 3301040502080001 | AR4: 3301040608700005 | AS4: Cilacap | AT4: 25786 | AV4: 3301044703750005 | AW4: Cilacap | AX4: 27460 | BA4: Islam | BH4: Mohammad Sanusi, S.H.I. | BI4: 786961 | BJ4: Dr. Mhd. Lailan Arqam, M.Pd. | BK4: - / 895 833
A5: 4 | B5: D | C5: A | D5: 11607 | E5: 010502043 | F5: Feris Lutfi Hilal Mahadi | G5: 17 Juli 2023 | J5: 1 | K5: 1 | M5: Laki-laki | N5: Magelang | P5: 40490 | Q5: 8 November 2010 | S5: Islam | T5: Mergangsan Lor MG II/1098 YK RT 045 RW 014 Wirogunan Mergangsan Kota Yogyakarta DIY 55151 | U5: 55151 | V5: Wirogunan | W5: Mergangsan | X5: Kota Yogyakarta | Y5: DI Yogyakarta | Z5: MTs Mu'allimin Muh Yogyakarta | AA5: Jalan Suroto 5 Padukuhan Jl. Gn. Bulu, Bandut Lor, Argorejo, Kec. Sedayu, Kabupaten Bantul, Daerah Istimewa Yogyakarta 55757 | AC5: Samsu Hartanto | AD5: Islam | AE5: SMA | AF5: Karyawan Swasta | AH5: 08179440384 | AJ5: Rohmiyatun | AK5: Islam | AL5: SMP | AM5: Ibu Rumah Tangga | BA5: Islam | BH5: Mohammad Sanusi, S.H.I. | BI5: 786961 | BJ5: Dr. Mhd. Lailan Arqam, M.Pd. | BK5: - / 895 833
A6: 5 | B6: B | C6: A | D6: 11608 | E6: 3112084736 | F6: Firaz Tsaqeffano | G6: 17 Juli 2023 | J6: 2 | K6: 2 | M6: Laki-laki | N6: Banyumas | P6: 40736 | Q6: 12 Juli 2011 | S6: Islam | T6: Perumahan Pabuaran Indah no 24 Grendeng Purwokerto Utara Banyumas Jawa Tengah 53122 | U6: 53122 | V6: Grendeng | W6: Purwokerto Utara | X6: Banyumas | Y6: Jawa Tengah | Z6: MTs Mu'allimin Muh Yogyakarta | AA6: Jalan Suroto 5 Padukuhan Jl. Gn. Bulu, Bandut Lor, Argorejo, Kec. Sedayu, Kabupaten Bantul, Daerah Istimewa Yogyakarta 55758 | AC6: Prastowo Tri Witono | AD6: Islam | AE6: S1 | AF6: Pegawai BUMN | AH6: 081227883901 | AJ6: Fitri Hapsari Yuniarti | AK6: Islam | AL6: S1 | AM6: Wiraswasta | AZ6: Franky Yoga Anggara | BA6: Islam | BB6: SMA | BC6: Perangkat Desa | BD6: Jaten RT 01 Sendangsari Pajangan Bantul DIY | BH6: Mohammad Sanusi, S.H.I. | BI6: 786961 | BJ6: Dr. Mhd. Lailan Arqam, M.Pd. | BK6: - / 895 833
A7: 6 | B7: E | C7: A | D7: 11609 | E7: 0111152815 | F7: Fuad Imtiyaz Mubarok | G7: 17 Juli 2023 | J7: 1 | K7: 2 | M7: Laki-laki | N7: Jakarta | P7: 40604 | Q7: 2 Maret 2011 | S7: Islam | T7: Jalan Basuki No. 2G R T 006 RW 006 Cilangkap Cipayung Jakarta Timur DKI Jakarta 13870 | U7: 13870 | V7: Cilangkap | W7: Cipayung | X7: Jakarta Timur | Y7: DKI Jakarta | Z7: MTs Mu'allimin Muh Yogyakarta | AA7: Jalan Suroto 5 Padukuhan Jl. Gn. Bulu, Bandut Lor, Argorejo, Kec. Sedayu, Kabupaten Bantul, Daerah Istimewa Yogyakarta 55759 | AC7: Achmad Mubarok | AD7: Islam | AE7: S1 | AF7: PNS | AH7: 081384815108 | AJ7: Siti Fatimah | AK7: Islam | AL7: S1 | AM7: Ibu Rumah Tangga | BA7: Islam | BH7: Mohammad Sanusi, S.H.I. | BI7: 786961 | BJ7: Dr. Mhd. Lailan Arqam, M.Pd. | BK7: - / 895 833
A8: 7 | B8: F | C8: A | D8: 11616 | E8: 0112858971 | F8: Habiburrahman Al Azizi | G8: 17 Juli 2023 | J8: 1 | K8: 1 | M8: Laki-laki | N8: Boyolali | P8: 40572 | Q8: 29 Januari 2011 | S8: Islam | T8: Dk VII Dukuh Puron RT 048 Trimurti Srandakan Bantul DIY 55762 | U8: 55762 | V8: Trimurti | W8: Srandakan | X8: Bantul | Y8: DI Yogyakarta | Z8: MTs Mu'allimin Muh Yogyakarta | AA8: Jalan Suroto 5 Padukuhan Jl. Gn. Bulu, Bandut Lor, Argorejo, Kec. Sedayu, Kabupaten Bantul, Daerah Istimewa Yogyakarta 55760 | AC8: (Alm.) Abdul Razaq | AD8: Islam | AJ8: Ani Widyaningsih | AK8: Islam | AM8: Lainnya | AO8: 085327963630 | AQ8: 3402012107220003 | BA8: Islam | BH8: Mohammad Sanusi, S.H.I. | BI8: 786961 | BJ8: Dr. Mhd. Lailan Arqam, M.Pd. | BK8: - / 895 833
A9: 8 | B9: C | C9: A | D9: 11624 | E9: 0112825165 | F9: Hail Kaisan Izzati | G9: 17 Juli 2023 | J9: 1 | K9: 2 | M9: Laki-laki | N9: Cilacap | P9: 40743 | Q9: 19 Juli 2011 | S9: Islam | T9: Jenang RT 003/019 Majenang Cilacap Jawa Tengah 53257 | U9: 53257 | V9: Jenang | W9: Majenang | X9: Cilacap | Y9: Jawa Tengah | Z9: MTs Mu'allimin Muh Yogyakarta | AA9: Jalan Suroto 5 Padukuhan Jl. Gn. Bulu, Bandut Lor, Argorejo, Kec. Sedayu, Kabupaten Bantul, Daerah Istimewa Yogyakarta 55761 | AC9: Arif Budi Santosa | AD9: Islam | AE9: D-III | AF9: Karyawan Swasta | AH9: 0856013016310 | AJ9: Irma Yuliastuti | AK9: Islam | AL9: S1 | AM9: Guru | BA9: Islam | BH9: Mohammad Sanusi, S.H.I. | BI9: 786961 | BJ9: Dr. Mhd. Lailan Arqam, M.Pd. | BK9: - / 895 833
A10: 9 | B10: H | C10: A | D10: 11625 | E10: 0112205063 | F10: Haiz Elhaq Rahman | G10: 17 Juli 2023 | J10: 3 | K10: 5 | M10: Laki-laki | N10: Cairo | O10: 40736 | P10: 40736 | Q10: 12 Juli 2011 | S10: Islam | T10: Jl. Caringin Komplek Fizhilala Al Quran RT 004 RW 012 Sayang Jatinangor Sumedang Jawa Barat 45363 | U10: 45363 | V10: Sayang | W10: Jatinangor | X10: Sumedang | Y10: Jawa Barat | Z10: MTs Mu'allimin Muh Yogyakarta | AA10: Jalan Suroto 5 Padukuhan Jl. Gn. Bulu, Bandut Lor, Argorejo, Kec. Sedayu, Kabupaten Bantul, Daerah Istimewa Yogyakarta 55762 | AC10: Cecep Taufikurrohman | AD10: Islam | AE10: S1 | AF10: Wiraswasta | AH10: 081394765323 | AJ10: Nurjanah Sholihah | AK10: Islam | AL10: S1 | AM10: Ibu Rumah Tangga | BA10: Islam | BH10: Mohammad Sanusi, S.H.I. | BI10: 786961 | BJ10: Dr. Mhd. Lailan Arqam, M.Pd. | BK10: - / 895 833
A11: 10 | B11: D | C11: A | D11: 11626 | E11: 0119197225 | F11: Hamzah Fatih Almubarok | G11: 17 Juli 2023 | J11: 1 | K11: 2 | M11: Laki-laki | N11: Yogyakarta | P11: 40596 | Q11: 22 Februari 2011 | S11: Islam | T11: Sembungan RT 003 Bangunjiwo Kasihan Bantul DIY 55184 | U11: 55184 | V11: Bangunjiwo | W11: Kasihan | X11: Bantul | Y11: DI Yogyakarta | Z11: MTs Mu'allimin Muh Yogyakarta | AA11: Jalan Suroto 5 Padukuhan Jl. Gn. Bulu, Bandut Lor, Argorejo, Kec. Sedayu, Kabupaten Bantul, Daerah Istimewa Yogyakarta 55763 | AC11: Yudhi Wiyoko | AD11: Islam | AE11: S1 | AF11: Guru | AH11: +62 895-2732-8954 | AJ11: Muslihah | AK11: Islam | AL11: S1 | AM11: Guru | AO11: 0895323303952 | BA11: Islam | BH11: Mohammad Sanusi, S.H.I. | BI11: 786961 | BJ11: Dr. Mhd. Lailan Arqam, M.Pd. | BK11: - / 895 833
A12: 11 | B12: D | C12: A | D12: 11660 | E12: 0109202081 | F12: M.Dafa Wafiqul Azhar | G12: 17 Juli 2023 | J12: 1 | K12: 1 | M12: Laki-laki | N12: Lamongan | P12: 40284 | Q12: 16 April 2010 | S12: Islam | T12: Dsn. Bancak Wetan RT 001 RW 010 Krogowanan Sawangan Magelang Jawa Tengah 55481 | U12: 55481 | V12: Krogowanan | W12: Sawangan | X12: Magelang | Y12: Jawa Tengah | Z12: MTs Mu'allimin Muh Yogyakarta | AA12: Jalan Suroto 5 Padukuhan Jl. Gn. Bulu, Bandut Lor, Argorejo, Kec. Sedayu, Kabupaten Bantul, Daerah Istimewa Yogyakarta 55764 | AC12: Anwarudin | AD12: Islam | AE12: S1 | AF12: Karyawan Swasta | AJ12: Nur Chayati | AK12: Islam | AL12: S1 | AM12: Karyawan Swasta | AO12: 081228258535 | BA12: Islam | BH12: Mohammad Sanusi, S.H.I. | BI12: 786961 | BJ12: Dr. Mhd. Lailan Arqam, M.Pd. | BK12: - / 895 833
A13: 12 | B13: G | C13: A | D13: 11677 | E13: 0104224489 | F13: Muhamad Azriel Akbar Setya Putra | G13: 17 Juli 2023 | J13: 1 | K13: 1 | M13: Laki-laki | N13: Grobogan | P13: 40468 | Q13: 17 Oktober 2010 | S13: Islam | T13: Getaspejaten RT 010 RW 004 Jati Kudus Jawa Tengah 59343 | U13: 59343 | V13: Getaspejaten | W13: Jati | X13: Kudus | Y13: Jawa Tengah | Z13: MTs Mu'allimin Muh Yogyakarta | AA13: Jalan Suroto 5 Padukuhan Jl. Gn. Bulu, Bandut Lor, Argorejo, Kec. Sedayu, Kabupaten Bantul, Daerah Istimewa Yogyakarta 55766 | AC13: Iwan Setiawan | AD13: Islam | AF13: Lainnya | AJ13: Tutik | AK13: Islam | AL13: Diploma I/II | AM13: PNS | AO13: 081325320871 | BA13: Islam | BH13: Mohammad Sanusi, S.H.I. | BI13: 786961 | BJ13: Dr. Mhd. Lailan Arqam, M.Pd. | BK13: - / 895 833
A14: 13 | B14: G | C14: A | D14: 11678 | E14: 3119592992 | F14: Muhammad Abid Al Dzaka | G14: 17 Juli 2023 | J14: 2 | K14: 3 | M14: Laki-laki | N14: Sleman | P14: 39502 | Q14: 16 Mei 2008 | S14: Islam | T14: Babadan IV RT 003 RW 009 Sendangagung Minggir Sleman DIY 55562 | U14: 55562 | V14: Sendangagung | W14: Minggir | X14: Sleman | Y14: DI Yogyakarta | Z14: MTs Mu'allimin Muh Yogyakarta | AA14: Jalan Suroto 5 Padukuhan Jl. Gn. Bulu, Bandut Lor, Argorejo, Kec. Sedayu, Kabupaten Bantul, Daerah Istimewa Yogyakarta 55767 | AC14: Indra Mulyani | AD14: Islam | AE14: SMA | AF14: Wiraswasta | AJ14: Ristiana Kuntari | AK14: Islam | AL14: S1 | AM14: Guru | AO14: 085100507934 | BA14: Islam | BH14: Mohammad Sanusi, S.H.I. | BI14: 786961 | BJ14: Dr. Mhd. Lailan Arqam, M.Pd. | BK14: - / 895 833
A15: 14 | B15: A | C15: A | D15: 11659 | E15: 0103157116 | F15: M. Abyan Qisthi Nabhani | G15: 17 Juli 2023 | J15: 1 | K15: 2 | M15: Laki-laki | N15: Pekalongan | P15: 40518 | Q15: 6 Desember 2010 | S15: Islam | T15: Podo Gg. 2B RT 011 RW 002 Kedungwuni Pekalongan Jawa Tengah 51173 | U15: 51173 | V15: Podo | W15: Kedungwuni | X15: Pekalongan | Y15: Jawa Tengah | Z15: MTs Mu'allimin Muh Yogyakarta | AA15: Jalan Suroto 5 Padukuhan Jl. Gn. Bulu, Bandut Lor, Argorejo, Kec. Sedayu, Kabupaten Bantul, Daerah Istimewa Yogyakarta 55768 | AC15: Muh. Bakrin | AD15: Islam | AE15: SMA | AF15: Wiraswasta | AH15: 085700420814 | AJ15: Fitriana | AK15: Islam | AL15: S1 | AM15: Guru | AO15: 085642602276 | AQ15: 3326130807140001 | AR15: 3326130104810021 | AS15: Pekalongan | AT15: 29677 | AV15: 3326136004840002 | AW15: Pekalongan | AX15: 30792 | BA15: Islam | BH15: Mohammad Sanusi, S.H.I. | BI15: 786961 | BJ15: Dr. Mhd. Lailan Arqam, M.Pd. | BK15: - / 895 833
A16: 15 | B16: E | C16: A | D16: 11687 | E16: 0118383409 | F16: Muhammad Almairi Akhyar | G16: 17 Juli 2023 | J16: 2 | K16: 2 | M16: Laki-laki | N16: Manggar | P16: 40840 | Q16: 24 Oktober 2011 | S16: Islam | T16: Dsn. Padang II RT 008 RW 004 Padang Manggar Belitung Timur Kepulauan Bangka Belitung 33516 | U16: 33516 | V16: Padang | W16: Manggar | X16: Belitung Timur | Y16: Kepulauan Bangka Belitung | Z16: MTs Mu'allimin Muh Yogyakarta | AA16: Jalan Suroto 5 Padukuhan Jl. Gn. Bulu, Bandut Lor, Argorejo, Kec. Sedayu, Kabupaten Bantul, Daerah Istimewa Yogyakarta 55769 | AC16: Agustian | AD16: Islam | AE16: S1 | AF16: PNS | AH16: 081367242505 | AJ16: Nurlaili Fitriyah | AK16: Islam | AL16: D-III | AM16: PNS | BA16: Islam | BH16: Mohammad Sanusi, S.H.I. | BI16: 786961 | BJ16: Dr. Mhd. Lailan Arqam, M.Pd. | BK16: - / 895 833
A17: 16 | B17: C | C17: A | D17: 11699 | E17: 0114574227 | F17: Muhammad Burhanuddin Robbani | G17: 17 Juli 2023 | J17: 2 | K17: 2 | M17: Laki-laki | N17: Jakarta | P17: 40617 | Q17: 15 Maret 2011 | S17: Islam | T17: Srengseng No 2 RT 002 RW 002 Srengseng Kembangan Jakarta Barat DKI Jakarta 11630 | U17: 11630 | V17: Srengseng | W17: Kembangan | X17: Jakarta Barat | Y17: DKI Jakarta | Z17: MTs Mu'allimin Muh Yogyakarta | AA17: Jalan Suroto 5 Padukuhan Jl. Gn. Bulu, Bandut Lor, Argorejo, Kec. Sedayu, Kabupaten Bantul, Daerah Istimewa Yogyakarta 55770 | AC17: Nurhadi | AD17: Islam | AE17: S1 | AF17: Karyawan Swasta | AJ17: Nur'ani | AK17: Islam | AL17: S1 | AM17: Ibu Rumah Tangga | AO17: 08119888395 | BA17: Islam | BH17: Mohammad Sanusi, S.H.I. | BI17: 786961 | BJ17: Dr. Mhd. Lailan Arqam, M.Pd. | BK17: - / 895 833
A18: 17 | B18: G | C18: A | D18: 11701 | E18: 0116953353 | F18: Muhammad Dwilutfan Ahda | G18: 17 Juli 2023 | J18: 2 | K18: 4 | M18: Laki-laki | N18: Belitung | P18: 40836 | Q18: 20 Oktober 2011 | S18: Islam | T18: Dsn. Pancur I RT 001 RW 001 Padang Manggar Belitung Timur Kepulauan Bangka Belitung 33516 | U18: 33516 | V18: Padang | W18: Manggar | X18: Belitung Timur | Y18: Kepulauan Bangka Belitung | Z18: MTs Mu'allimin Muh Yogyakarta | AA18: Jalan Suroto 5 Padukuhan Jl. Gn. Bulu, Bandut Lor, Argorejo, Kec. Sedayu, Kabupaten Bantul, Daerah Istimewa Yogyakarta 55771 | AC18: Samlawi | AD18: Islam | AE18: S1 | AF18: PNS | AH18: 081930205518 | AJ18: Ria Rita | AK18: Islam | AL18: S1 | AM18: PNS | BA18: Islam | BH18: Mohammad Sanusi, S.H.I. | BI18: 786961 | BJ18: Dr. Mhd. Lailan Arqam, M.Pd. | BK18: - / 895 833
A19: 18 | B19: F | C19: A | D19: 11722 | E19: 0112036009 | F19: Muhammad Ibra Bekti Rohmadhoni | G19: 17 Juli 2023 | J19: 1 | K19: 1 | M19: Laki-laki | N19: Bojonegoro | P19: 40759 | Q19: 4 Agustus 2011 | S19: Islam | T19: Jl. Muh. Husni Thamrin RT 001 RW 002 Tomba Wolio Kota Baubau Sulawesi Tenggara 93712 | U19: 93712 | V19: Tomba | W19: Wolio | X19: Kota Baubau | Y19: Sulawesi Tenggara | Z19: MTs Mu'allimin Muh Yogyakarta | AA19: Jalan Suroto 5 Padukuhan Jl. Gn. Bulu, Bandut Lor, Argorejo, Kec. Sedayu, Kabupaten Bantul, Daerah Istimewa Yogyakarta 55774 | AC19: Imam Subekti | AD19: Islam | AE19: SMP | AF19: Wiraswasta | AH19: 081330191549 | AJ19: Aenur Rohmah | AK19: Islam | AL19: SMP | AM19: Ibu Rumah Tangga | BA19: Islam | BH19: Mohammad Sanusi, S.H.I. | BI19: 786961 | BJ19: Dr. Mhd. Lailan Arqam, M.Pd. | BK19: - / 895 833
A20: 19 | B20: B | C20: A | D20: 11728 | E20: 0109802442 | F20: Muhammad Naufal Rasyiid Jaya | G20: 17 Juli 2023 | J20: 1 | K20: 1 | M20: Laki-laki | N20: Sleman | P20: 40373 | Q20: 14 Juli 2010 | S20: Islam | T20: Bodeh RT 001 RW 023 Ambarketawang Gamping Sleman DIY 55294 | U20: 55294 | V20: Ambarketawang | W20: Gamping | X20: Sleman | Y20: DI Yogyakarta | Z20: MTs Mu'allimin Muh Yogyakarta | AA20: Jalan Suroto 5 Padukuhan Jl. Gn. Bulu, Bandut Lor, Argorejo, Kec. Sedayu, Kabupaten Bantul, Daerah Istimewa Yogyakarta 55775 | AC20: Supangat Infantri Jaya | AD20: Islam | AE20: SMA | AF20: PNS | AH20: 081838205958 | AJ20: Budi Lestari | AK20: Islam | AL20: SMA | AM20: Ibu Rumah Tangga | AQ20: 3404013007100014 | AR20: 340401604770002 | AS20: Sleman | AT20: 28221 | AV20: 3402084210770004 | AW20: Bantul | AX20: 28400 | BA20: Islam | BH20: Mohammad Sanusi, S.H.I. | BI20: 786961 | BJ20: Dr. Mhd. Lailan Arqam, M.Pd. | BK20: - / 895 833
A21: 20 | B21: E | C21: A | D21: 11731 | E21: 3103569331 | F21: Muhammad Rafa Arrayyan | G21: 17 Juli 2023 | J21: 1 | K21: 2 | M21: Laki-laki | N21: Jakarta | P21: 40382 | Q21: 23 Juli 2010 | S21: Islam | T21: Jl. Swadaya PLN Klender RT 003 RW 002 Jatinegara Cakung Jakarta Timur DKI Jakarta 13930 | U21: 13930 | V21: Jatinegara | W21: Cakung | X21: Jakarta Timur | Y21: DKI Jakarta | Z21: MTs Mu'allimin Muh Yogyakarta | AA21: Jalan Suroto 5 Padukuhan Jl. Gn. Bulu, Bandut Lor, Argorejo, Kec. Sedayu, Kabupaten Bantul, Daerah Istimewa Yogyakarta 55776 | AC21: Trinanda Munfaji (alm.) | AD21: Islam | AJ21: Nur Robiatul Adawiyah | AK21: Islam | AL21: S1 | AM21: Guru | AO21: 081289623359 | BA21: Islam | BH21: Mohammad Sanusi, S.H.I. | BI21: 786961 | BJ21: Dr. Mhd. Lailan Arqam, M.Pd. | BK21: - / 895 833
A22: 21 | B22: H | C22: A | D22: 11735 | E22: 0119936984 | F22: Muhammad Razan Al Azka Panglimunan | G22: 17 Juli 2023 | J22: 1 | K22: 1 | M22: Laki-laki | N22: Solo | P22: 40694 | Q22: 31 Mei 2011 | S22: Islam | T22: Jl. Sekar Jagad 1 No. 21A RT 004 RW 001 Pajang Laweyan Surakarta Jawa Tengah 57146 | U22: 57146 | V22: Pajang | W22: Laweyan | X22: Kota Surakarta | Y22: Jawa Tengah | Z22: MTs Mu'allimin Muh Yogyakarta | AA22: Jalan Suroto 5 Padukuhan Jl. Gn. Bulu, Bandut Lor, Argorejo, Kec. Sedayu, Kabupaten Bantul, Daerah Istimewa Yogyakarta 55777 | AC22: Muhammad Iqbal | AD22: Islam | AJ22: Siti Amirul Ulfah | AK22: Islam | AL22: S1 | AM22: Ibu Rumah Tangga | BA22: Islam | BH22: Mohammad Sanusi, S.H.I. | BI22: 786961 | BJ22: Dr. Mhd. Lailan Arqam, M.Pd. | BK22: - / 895 833
A23: 22 | B23: A | C23: A | D23: 11762 | E23: 0103659765 | F23: Nizham Ziyad Ar Rasyiediin | G23: 17 Juli 2023 | J23: 1 | K23: 1 | M23: Laki-laki | N23: Taman Sari | P23: 40427 | Q23: 6 September 2010 | S23: Islam | T23: Jl. Tani RT 006 RW 004 Pringsewu Barat Pringsewu Lampung 35373 | U23: 35373 | V23: Pringsewu Barat | W23: Pringsewu | X23: Pringsewu | Y23: Lampung | Z23: MTs Mu'allimin Muh Yogyakarta | AA23: Jalan Suroto 5 Padukuhan Jl. Gn. Bulu, Bandut Lor, Argorejo, Kec. Sedayu, Kabupaten Bantul, Daerah Istimewa Yogyakarta 55778 | AC23: Edi Susanto, SE | AD23: Islam | AE23: S1 | AF23: Wiraswasta | AH23: 085269569197 | AJ23: Indarti Suryaningsih, SE | AK23: Islam | AL23: S1 | AM23: Karyawan Swasta | AQ23: 1810011110160007 | AR23: 180911306840004 | AS23: Mujirahayu | AT23: 30846 | AV23: 1809015911850005 | AW23: Kemiling | AX23: 31370 | BA23: Islam | BH23: Mohammad Sanusi, S.H.I. | BI23: 786961 | BJ23: Dr. Mhd. Lailan Arqam, M.Pd. | BK23: - / 895 833
A24: 23 | B24: E | C24: A | D24: 11800 | E24: 0116601897 | F24: Rohman Qolbi Salim | G24: 17 Juli 2023 | J24: 3 | K24: 2 | M24: Laki-laki | N24: Rimbo Bujang | P24: 40570 | Q24: 27 Januari 2011 | S24: Islam | T24: Jl. Jendral Sudirman RT 001 RW 004 Mandiri Agung Rimbo Bujang Tebo Jambi 37551 | U24: 37551 | V24: Mandiri Agung | W24: Rimbo Bujang | X24: Tebo | Y24: Jambi | Z24: MTs Mu'allimin Muh Yogyakarta | AA24: Jalan Suroto 5 Padukuhan Jl. Gn. Bulu, Bandut Lor, Argorejo, Kec. Sedayu, Kabupaten Bantul, Daerah Istimewa Yogyakarta 55779 | AC24: Busri, S.Pd. | AD24: Islam | AE24: S1 | AF24: PNS | AH24: 082374722650 | AJ24: Nurul Hidayah | AK24: Islam | AL24: SMA | AM24: Ibu Rumah Tangga | BA24: Islam | BH24: Mohammad Sanusi, S.H.I. | BI24: 786961 | BJ24: Dr. Mhd. Lailan Arqam, M.Pd. | BK24: - / 895 833
A25: 24 | B25: B | C25: A | D25: 11810 | E25: 0112840730 | F25: Syabil Angkasa Putra Solissa | G25: 17 Juli 2023 | J25: 2 | K25: 2 | M25: Laki-laki | N25: Ambon | P25: 40721 | Q25: 27 Juni 2011 | S25: Islam | T25: Desa Lektama Namrole Buru Selatan Maluku | V25: Lektama | W25: Namrole | X25: Buru Selatan | Y25: Maluku | Z25: MTs Mu'allimin Muh Yogyakarta | AA25: Jalan Suroto 5 Padukuhan Jl. Gn. Bulu, Bandut Lor, Argorejo, Kec. Sedayu, Kabupaten Bantul, Daerah Istimewa Yogyakarta 55780 | AC25: Yasir Arafat Solissa | AD25: Islam | AE25: SMA | AF25: POLRI | AJ25: Miram Hitimala | AK25: Islam | AL25: SMA | AM25: Ibu Rumah Tangga | AZ25: Abdul Basir Solissa | BA25: Islam | BB25: S2 | BC25: Dosen | BF25: 082141317156 | BH25: Mohammad Sanusi, S.H.I. | BI25: 786961 | BJ25: Dr. Mhd. Lailan Arqam, M.Pd. | BK25: - / 895 833
A26: 25 | B26: E | C26: A | D26: 11819 | E26: 0112861218 | F26: Wazni Nawaf Al-Farras | G26: 17 Juli 2023 | J26: 1 | K26: 1 | M26: Laki-laki | N26: Sleman | P26: 40647 | Q26: 14 April 2011 | S26: Islam | T26: Ngentak RT 066 Argorejo Sedayu Bantul DIY 55752 | U26: 55752 | V26: Argorejo | W26: Sedayu | X26: Bantul | Y26: DI Yogyakarta | Z26: MTs Mu'allimin Muh Yogyakarta | AA26: Jalan Suroto 5 Padukuhan Jl. Gn. Bulu, Bandut Lor, Argorejo, Kec. Sedayu, Kabupaten Bantul, Daerah Istimewa Yogyakarta 55781 | AC26: Agus Suprianto | AD26: Islam | AE26: S1 | AF26: Karyawan Swasta | AJ26: Alif Maziyah | AK26: Islam | AL26: S1 | AM26: Wiraswasta | AO26: 08156815406 | BA26: Islam | BH26: Mohammad Sanusi, S.H.I. | BI26: 786961 | BJ26: Dr. Mhd. Lailan Arqam, M.Pd. | BK26: - / 895 833
A27: 26 | B27: C | C27: A | D27: 11823 | E27: 0112852073 | F27: Yusuf Aydin Hylmi Asadel | G27: 17 Juli 2023 | J27: 2 | K27: 2 | M27: Laki-laki | N27: Semarang | P27: 40569 | Q27: 26 Januari 2011 | S27: Islam | T27: Botton 1 472 RT 003 RW 005 Magelang Tengah Kota Magelang Jawa Tengah 56117 | U27: 56117 | V27: Magelang | W27: Magelang Tengah | X27: Kota Magelang | Y27: Jawa Tengah | Z27: MTs Mu'allimin Muh Yogyakarta | AA27: Jalan Suroto 5 Padukuhan Jl. Gn. Bulu, Bandut Lor, Argorejo, Kec. Sedayu, Kabupaten Bantul, Daerah Istimewa Yogyakarta 55782 | AC27: Nanang Yudo Cahyono | AD27: Islam | AE27: S1 | AF27: PNS | AH27: 085647639364 | AJ27: Maftuhah | AK27: Islam | AL27: SMA | AM27: Ibu Rumah Tangga | BA27: Islam | BH27: Mohammad Sanusi, S.H.I. | BI27: 786961 | BJ27: Dr. Mhd. Lailan Arqam, M.Pd. | BK27: - / 895 833
A28: 1 | B28: B | C28: B | D28: 11535 | E28: 0113563650 | F28: Ahmad Azzam Huluq | G28: 17 Juli 2023 | J28: 3 | K28: 2 | M28: Laki-laki | N28: Serang | P28: 40612 | Q28: 10 Maret 2011 | S28: Islam | T28: Lingk Lebak Gempol RT 001 RW 010 Panancangan Cipocok Jaya Kota Serang Banten 42124 | U28: 42124 | V28: Panancangan | W28: Cipocok Jaya | X28: Kota Serang | Y28: Banten | Z28: MTs Mu'allimin Muh Yogyakarta | AA28: Jalan Suroto 5 Padukuhan Jl. Gn. Bulu, Bandut Lor, Argorejo, Kec. Sedayu, Kabupaten Bantul, Daerah Istimewa Yogyakarta 55783 | AC28: H. Irfan Husnul Huluq, SE | AD28: Islam | AE28: S1 | AF28: PNS | AJ28: Yuliawati | AK28: Islam | AL28: S1 | AM28: Ibu Rumah Tangga | AO28: 08787949101 | AQ28: 3604021801050100 | AR28: 3604022805770476 | AS28: Bandung | AT28: 28273 | AV28: 3604024307760477 | AW28: Serang | AX28: 27947 | BA28: Islam | BH28: Muhammad Taffani Kusumawardana, S.Si. | BI28: 1408764 | BJ28: Dr. Mhd. Lailan Arqam, M.Pd. | BK28: - / 895 833
A29: 2 | B29: F | C29: B | D29: 11536 | E29: 0106466461 | F29: Ahmad Faith Aly Ishar | G29: 17 Juli 2023 | J29: 3 | K29: 2 | M29: Laki-laki | N29: Makassar | P29: 40480 | Q29: 29 Oktober 2010 | S29: Islam | T29: BTN Minasa Upa Blok L 15 No 15 RT 005 RW 014 Minasa Upa Rappocini Kota Makassar Sulawesi Selatan 90221 | U29: 90221 | V29: Minasa Upa | W29: Rappocini | X29: Kota Makassar | Y29: Sulawesi Selatan | Z29: MTs Mu'allimin Muh Yogyakarta | AA29: Jalan Suroto 5 Padukuhan Jl. Gn. Bulu, Bandut Lor, Argorejo, Kec. Sedayu, Kabupaten Bantul, Daerah Istimewa Yogyakarta 55784 | AC29: H. Hasbudi, ST | AD29: Islam | AE29: S1 | AF29: Karyawan Swasta | AJ29: Ramlah Mustara | AK29: Islam | AL29: S1 | AM29: PNS | BA29: Islam | BH29: Muhammad Taffani Kusumawardana, S.Si. | BI29: 1408764 | BJ29: Dr. Mhd. Lailan Arqam, M.Pd. | BK29: - / 895 833
A30: 3 | B30: F | C30: B | D30: 11540 | E30: 0118001666 | F30: Ahmad Syamil Zakaria | G30: 17 Juli 2023 | J30: 3 | K30: 2 | M30: Laki-laki | N30: Padang | P30: 40630 | Q30: 28 Maret 2011 | S30: Islam | T30: Jl. B. Zein Hamid Gg Kelaurga No. 14 A LK II Titi Kuning Medan Johor Kota Medan Sumatera Utara 20146 | U30: 20146 | V30: Titi Kuning | W30: Medan Johor | X30: Kota Medan | Y30: Sumatera Utara | Z30: MTs Mu'allimin Muh Yogyakarta | AA30: Jalan Suroto 5 Padukuhan Jl. Gn. Bulu, Bandut Lor, Argorejo, Kec. Sedayu, Kabupaten Bantul, Daerah Istimewa Yogyakarta 55785 | AC30: Didik Darmadi | AD30: Islam | AE30: S2 | AF30: PNS | AH30: 081319303814 | AJ30: Annisah Husni Daulay | AK30: Islam | AL30: S2 | AM30: PNS | BA30: Islam | BH30: Muhammad Taffani Kusumawardana, S.Si. | BI30: 1408764 | BJ30: Dr. Mhd. Lailan Arqam, M.Pd. | BK30: - / 895 833
A31: 4 | B31: E | C31: B | D31: 11549 | E31: 0109732828 | F31: Amar Maulana Ardani | G31: 17 Juli 2023 | J31: 4 | K31: 3 | M31: Laki-laki | N31: Wonosobo | P31: 40320 | Q31: 22 Mei 2010 | S31: Islam | T31: Mataraman RT 001 RW 005 Wonosobo Timur Wonosobo Jawa Tengah 56311 | U31: 56311 | V31: Wonosobo Timur | W31: Wonosobo | X31: Wonosobo | Y31: Jawa Tengah | Z31: MTs Mu'allimin Muh Yogyakarta | AA31: Jalan Suroto 5 Padukuhan Jl. Gn. Bulu, Bandut Lor, Argorejo, Kec. Sedayu, Kabupaten Bantul, Daerah Istimewa Yogyakarta 55786 | AC31: Chamim Ardani | AD31: Islam | AE31: SMA | AF31: Pedagang | AH31: 085290670867 | AJ31: Nuryanti | AK31: Islam | BA31: Islam | BH31: Muhammad Taffani Kusumawardana, S.Si. | BI31: 1408764 | BJ31: Dr. Mhd. Lailan Arqam, M.Pd. | BK31: - / 895 833
A32: 5 | B32: E | C32: B | D32: 11550 | E32: 0101109394 | F32: Amaru Dimitar Seja Maharota | G32: 17 Juli 2023 | J32: 2 | K32: 2 | M32: Laki-laki | N32: Magetan | P32: 40281 | Q32: 13 April 2010 | S32: Islam | T32: Jln. Hasanudin RT 004 RW 005 Selosari Magetan Jawa Timur | V32: Selosari | W32: Magetan | X32: Magetan | Y32: Jawa Timur | Z32: MTs Mu'allimin Muh Yogyakarta | AA32: Jalan Suroto 5 Padukuhan Jl. Gn. Bulu, Bandut Lor, Argorejo, Kec. Sedayu, Kabupaten Bantul, Daerah Istimewa Yogyakarta 55787 | AC32: Heru Riyanto | AD32: Islam | AE32: S1 | AF32: PNS | AH32: 081336742400 | AJ32: Amaliya Nur Hasanah | AK32: Islam | AL32: S1 | AM32: Ibu Rumah Tangga | BA32: Islam | BH32: Muhammad Taffani Kusumawardana, S.Si. | BI32: 1408764 | BJ32: Dr. Mhd. Lailan Arqam, M.Pd. | BK32: - / 895 833
A33: 6 | B33: H | C33: B | D33: 11557 | E33: 3108936886 | F33: Arman Maulana | G33: 17 Juli 2023 | J33: 3 | K33: 3 | M33: Laki-laki | N33: Jakarta | P33: 40252 | Q33: 15 Maret 2010 | S33: Islam | T33: Jl. Rawa Bebek RT 010 RW 013 Penjaringan Jakarta Utara DKI Jakarta 14440 | U33: 14440 | V33: Penjaringan | W33: Penjaringan | X33: Jakarta Utara | Y33: DKI Jakarta | Z33: MTs Mu'allimin Muh Yogyakarta | AA33: Jalan Suroto 5 Padukuhan Jl. Gn. Bulu, Bandut Lor, Argorejo, Kec. Sedayu, Kabupaten Bantul, Daerah Istimewa Yogyakarta 55788 | AC33: Abdul Hamid | AD33: Islam | AE33: SMA | AF33: Karyawan Swasta | AJ33: Rubiyanti | AK33: Islam | AL33: SMP | AM33: Ibu Rumah Tangga | AO33: 082135433550 | BA33: Islam | BH33: Muhammad Taffani Kusumawardana, S.Si. | BI33: 1408764 | BJ33: Dr. Mhd. Lailan Arqam, M.Pd. | BK33: - / 895 833
A34: 7 | B34: B | C34: B | D34: 11559 | E34: 0107749826 | F34: Ashraf 'Ifathurrosydan | G34: 17 Juli 2023 | J34: 1 | K34: 2 | M34: Laki-laki | N34: Sragen | P34: 40331 | Q34: 2 Juni 2010 | S34: Islam | T34: Masaran Kulon RT 003 RW 002 Jati Masaran Sragen Jawa Tengah 57282 | U34: 57282 | V34: Jati | W34: Masaran | X34: Sragen | Y34: Jawa Tengah | Z34: MTs Mu'allimin Muh Yogyakarta | AA34: Jalan Suroto 5 Padukuhan Jl. Gn. Bulu, Bandut Lor, Argorejo, Kec. Sedayu, Kabupaten Bantul, Daerah Istimewa Yogyakarta 55789 | AC34: Hasan Rustamaji, S.Sn. | AD34: Islam | AE34: S1 | AF34: PNS | AJ34: Ida Rodliyah | AK34: Islam | AL34: S1 | AM34: Wiraswasta | AO34: 082277695266 | AQ34: 3314030802170003 | AR34: 3314031409800001 | AS34: Sragen | AT34: 29478 | AV34: 3314114502840001 | AW34: Sragen | AX34: 30717 | BA34: Islam | BH34: Muhammad Taffani Kusumawardana, S.Si. | BI34: 1408764 | BJ34: Dr. Mhd. Lailan Arqam, M.Pd. | BK34: - / 895 833
A35: 8 | B35: C | C35: B | D35: 11563 | E35: 0109930189 | F35: Aviciena Rafa Al Ghifari | G35: 17 Juli 2023 | J35: 1 | K35: 2 | M35: Laki-laki | N35: Yogyakarta | P35: 40471 | Q35: 20 Oktober 2010 | S35: Islam | T35: Sorosutan UH 6/928 RT 019 RW 006 Umbulharjo Kota Yogyakarta DIY 55162 | U35: 55162 | V35: Sorosutan | W35: Umbulharjo | X35: Kota Yogyakarta | Y35: DI Yogyakarta | Z35: MTs Mu'allimin Muh Yogyakarta | AA35: Jalan Suroto 5 Padukuhan Jl. Gn. Bulu, Bandut Lor, Argorejo, Kec. Sedayu, Kabupaten Bantul, Daerah Istimewa Yogyakarta 55790 | AC35: Hery Sukirno, S.H.I. | AD35: Islam | AE35: S1 | AF35: Karyawan Swasta | AH35: 081904086099 | AJ35: Martha Setyawati | AK35: Islam | AL35: S1 | AM35: Guru | BA35: Islam | BH35: Muhammad Taffani Kusumawardana, S.Si. | BI35: 1408764 | BJ35: Dr. Mhd. Lailan Arqam, M.Pd. | BK35: - / 895 833
A36: 9 | B36: D | C36: B | D36: 11568 | E36: 0114695074 | F36: Azharuddin Ahza Aprilian | G36: 17 Juli 2023 | J36: 5 | K36: 4 | M36: Laki-laki | N36: Yogyakarta | P36: 40640 | Q36: 7 April 2011 | S36: Islam | T36: Perum Baleasri Blok F-7 Pereng Dawe RT 013 RW 046 Balecatur Gamping Sleman Daerah Istimewa Yogyakarta | U36: 55295 | V36: Balecatur | W36: Gamping | X36: Sleman | Y36: Daerah Istimewa Yogyakarta | Z36: MTs Mu'allimin Muh Yogyakarta | AA36: Jalan Suroto 5 Padukuhan Jl. Gn. Bulu, Bandut Lor, Argorejo, Kec. Sedayu, Kabupaten Bantul, Daerah Istimewa Yogyakarta 55791 | AC36: Drs. Muslih | AD36: Islam | AE36: S1 | AF36: PNS | AJ36: Siti Khalimah | AK36: Islam | AL36: S1 | AM36: Ibu Rumah Tangga | BA36: Islam | BH36: Muhammad Taffani Kusumawardana, S.Si. | BI36: 1408764 | BJ36: Dr. Mhd. Lailan Arqam, M.Pd. | BK36: - / 895 833
A37: 10 | B37: A | C37: B | D37: 11611 | E37: 0115018402 | F37: Gardadin Rusydian Muhammad | G37: 17 Juli 2023 | J37: 1 | K37: 1 | M37: Laki-laki | N37: Sleman | P37: 40568 | Q37: 25 Januari 2011 | S37: Islam | T37: Jl. Delima II/73 Perum jambusari Indah Krajan RT 008 RW 065 Wedomartani Ngemplak Sleman DIY 55584 | U37: 55584 | V37: Wedomartani | W37: Ngemplak | X37: Sleman | Y37: DI Yogyakarta | Z37: MTs Mu'allimin Muh Yogyakarta | AA37: Jalan Suroto 5 Padukuhan Jl. Gn. Bulu, Bandut Lor, Argorejo, Kec. Sedayu, Kabupaten Bantul, Daerah Istimewa Yogyakarta 55792 | AC37: Muhammad Abduh | AD37: Islam | AE37: S1 | AF37: Wiraswasta | AH37: 083840005060 | AJ37: Bertalisa | AK37: Islam | AL37: S2 | AM37: Ibu Rumah Tangga | AQ37: 3404111703110003 | AR37: 3471101605810001 | AS37: Yogyakarta | AT37: 29722 | AV37: 3404115010800006 | AW37: Pendopo | AX37: 29504 | BA37: Islam | BH37: Muhammad Taffani Kusumawardana, S.Si. | BI37: 1408764 | BJ37: Dr. Mhd. Lailan Arqam, M.Pd. | BK37: - / 895 833
A38: 11 | B38: D | C38: B | D38: 11613 | E38: 0107481232 | F38: Gilang Cahyo Candrawimba | G38: 17 Juli 2023 | J38: 1 | K38: 1 | M38: Laki-laki | N38: Magelang | P38: 40394 | Q38: 4 Agustus 2010 | S38: Islam | T38: Dsn. Kuncen RT 001 RW 002 Ngablak Magelang Jawa Tengah 56194 | U38: 56194 | V38: Ngablak | W38: Ngablak | X38: Magelang | Y38: Jawa Tengah | Z38: MTs Mu'allimin Muh Yogyakarta | AA38: Jalan Suroto 5 Padukuhan Jl. Gn. Bulu, Bandut Lor, Argorejo, Kec. Sedayu, Kabupaten Bantul, Daerah Istimewa Yogyakarta 55793 | AC38: Heri Cahyono | AD38: Islam | AE38: S1 | AF38: Wiraswasta | AH38: 085292277795 | AJ38: Siti Mahmudah | AK38: Islam | AL38: S1 | AM38: Wiraswasta | BA38: Islam | BH38: Muhammad Taffani Kusumawardana, S.Si. | BI38: 1408764 | BJ38: Dr. Mhd. Lailan Arqam, M.Pd. | BK38: - / 895 833
A39: 12 | B39: D | C39: B | D39: 11620 | E39: 0109439388 | F39: Haidar Iftikarullah Aszuhdi | G39: 17 Juli 2023 | J39: 2 | K39: 2 | M39: Laki-laki | N39: Yogyakarta | P39: 40412 | Q39: 22 Agustus 2010 | S39: Islam | T39: Perum Griya Mandiri No. 1 RT 054 RW 015 Suryodiningratan Mantrijeron Kota Yogyakarta DIY 55141 | U39: 55141 | V39: Suryodiningratan | W39: Mantrijeron | X39: Kota Yogyakarta | Y39: DI Yogyakarta | Z39: MTs Mu'allimin Muh Yogyakarta | AA39: Jalan Suroto 5 Padukuhan Jl. Gn. Bulu, Bandut Lor, Argorejo, Kec. Sedayu, Kabupaten Bantul, Daerah Istimewa Yogyakarta 55794 | AC39: Alwansyah, ST | AD39: Islam | AE39: S1 | AF39: Karyawan Swasta | AH39: 08123488283 | AJ39: Anggarakasih Ardianto, SH | AK39: Islam | AL39: S1 | AM39: Karyawan Swasta | BA39: Islam | BH39: Muhammad Taffani Kusumawardana, S.Si. | BI39: 1408764 | BJ39: Dr. Mhd. Lailan Arqam, M.Pd. | BK39: - / 895 833
A40: 13 | B40: H | C40: B | D40: 11627 | E40: 0109855762 | F40: Hanan Al Atsari | G40: 17 Juli 2023 | J40: 4 | K40: 3 | M40: Laki-laki | N40: Bantul | P40: 40448 | Q40: 27 September 2010 | S40: Islam | T40: Sumber Dk. Balakan RT 001 Sumberagung Jetis Bantul DIY 55781 | U40: 55781 | V40: Sumberagung | W40: Jetis | X40: Bantul | Y40: DI Yogyakarta | Z40: MTs Mu'allimin Muh Yogyakarta | AA40: Jalan Suroto 5 Padukuhan Jl. Gn. Bulu, Bandut Lor, Argorejo, Kec. Sedayu, Kabupaten Bantul, Daerah Istimewa Yogyakarta 55795 | AC40: Noor Kunto Aribowo | AD40: Islam | AE40: D-IV | AF40: Perawat | AJ40: Pariyah | AK40: Islam | AL40: D-III | AM40: Ibu Rumah Tangga | AO40: 0895332725129 | BA40: Islam | BH40: Muhammad Taffani Kusumawardana, S.Si. | BI40: 1408764 | BJ40: Dr. Mhd. Lailan Arqam, M.Pd. | BK40: - / 895 833
...

Sheet PERKELAS
A1: PARALEL | B1: NO | C1: INDUK | D1: NISN | E1: NAMA SISWA | F1: Jenis Kelamin | G1: TEMPAT LAHIR | H1: TANGGAL LAHIR | I1: Agama | J1: Anak Ke | K1: Jml Saudara | L1: Alamat Tempat Tinggal | M1: KELURAHAN | N1: KECAMATAN | O1: Kabupaten/kota | P1: Provinsi | Q1: Asal Sekolah | R1: Alamat Sekolah | S1: Prestasi | T1: Nama Ayah | U1: Agama Ayah | V1: Pendidikan | W1: Pekerjaan | X1: Penghasilan | Y1: Telp | Z1: Email | AA1: Nama Ibu | AB1: Agama Ibu | AC1: Pendidikan | AD1: Pekerjaan | AE1: Penghasilan | AF1: Telp | AG1: Email | AH1: Nama Wali | AI1: Agama Wali | AJ1: Pendidikan | AK1: Pekerjaan | AL1: Alamat Wali | AM1: Penghasilan | AN1: Telp | AO1: Email | AP1: Nama WK
A2: A | B2: 1 | C2: ='BIO DATA'!#REF! -> #REF! | D2: ='BIO DATA'!#REF! -> #REF! | E2: ='BIO DATA'!#REF! -> #REF! | F2: ='BIO DATA'!#REF! -> #REF! | G2: ='BIO DATA'!#REF! -> #REF! | H2: ='BIO DATA'!#REF! -> #REF! | I2: ='BIO DATA'!#REF! -> #REF! | J2: ='BIO DATA'!#REF! -> #REF! | ... AP2: ='BIO DATA'!#REF! -> #REF!
A3: A | B3: 11 | C3: ='BIO DATA'!D2 -> 11543 | D3: ='BIO DATA'!E2 -> 3101049926 | E3: ='BIO DATA'!F2 -> Ainurrofiq Syamsudin | F3: ='BIO DATA'!M2 -> Laki-laki | G3: ='BIO DATA'!N2 -> Baranusa | H3: ='BIO DATA'!P2 -> 40330 | I3: ='BIO DATA'!S2 -> Islam | J3: ='BIO DATA'!J2 -> 1 | K3: ='BIO DATA'!K2 -> 2 | L3: ='BIO DATA'!T2 -> Jl. Imam Bonjol No. 143 RT 002 RW 001 Adang Buom Teluk Mutiara Alor Nusa Tenggara Timur | M3: ='BIO DATA'!V2 -> Adang Buom | N3: ='BIO DATA'!W2 -> Teluk Mutiara | O3: ='BIO DATA'!X2 -> Alor | P3: ='BIO DATA'!Y2 -> Nusa Tenggara Timur | Q3: ='BIO DATA'!Z2 -> MTs Mu'allimin Muh Yogyakarta | R3: ='BIO DATA'!AA2 -> Jalan Suroto 5 Padukuhan Jl. Gn. Bulu, Bandut Lor, Argorejo, Kec. Sedayu, Kabupaten Bantul, Daerah Istimewa Yogyakarta 55753 | S3: ='BIO DATA'!AB2 -> 0 | T3: ='BIO DATA'!AC2 -> Muhammad H. Sjamsuddin | ... AG3: ='BIO DATA'!AP2 -> 0 | AH3: ='BIO DATA'!AZ2 -> 0 | AI3: ='BIO DATA'!BA2 -> Islam | AJ3: ='BIO DATA'!BB2 -> 0 | AK3: ='BIO DATA'!BC2 -> 0 | AL3: ='BIO DATA'!BD2 -> 0 | AM3: ='BIO DATA'!BE2 -> 0 | AN3: ='BIO DATA'!BF2 -> 0 | AO3: ='BIO DATA'!BG2 -> 0 | AP3: ='BIO DATA'!BH2 -> Mohammad Sanusi, S.H.I.
A4: A | B4: 12 | C4: ='BIO DATA'!D3 -> 11586 | D4: ='BIO DATA'!E3 -> 0105875288 | E4: ='BIO DATA'!F3 -> Elka Maulana Iskandar | F4: ='BIO DATA'!M3 -> Laki-laki | G4: ='BIO DATA'!N3 -> Kudus | H4: ='BIO DATA'!P3 -> 40530 | I4: ='BIO DATA'!S3 -> Islam | J4: ='BIO DATA'!J3 -> 1 | K4: ='BIO DATA'!K3 -> 1 | L4: ='BIO DATA'!T3 -> Bae RT 001 RW 001 Bae Kudus Jawa Tengah | M4: ='BIO DATA'!V3 -> Bae | N4: ='BIO DATA'!W3 -> Bae | O4: ='BIO DATA'!X3 -> Kudus | P4: ='BIO DATA'!Y3 -> Jawa Tengah | Q4: ='BIO DATA'!Z3 -> MTs Mu'allimin Muh Yogyakarta | R4: ='BIO DATA'!AA3 -> Jalan Suroto 5 Padukuhan Jl. Gn. Bulu, Bandut Lor, Argorejo, Kec. Sedayu, Kabupaten Bantul, Daerah Istimewa Yogyakarta 55754 | S4: ='BIO DATA'!AB3 -> 0 | T4: ='BIO DATA'!AC3 -> Heri Iskandar | ... AG4: ='BIO DATA'!AP3 -> 0 | AH4: ='BIO DATA'!AZ3 -> 0 | AI4: ='BIO DATA'!BA3 -> Islam | AJ4: ='BIO DATA'!BB3 -> 0 | AK4: ='BIO DATA'!BC3 -> 0 | AL4: ='BIO DATA'!BD3 -> 0 | AM4: ='BIO DATA'!BE3 -> 0 | AN4: ='BIO DATA'!BF3 -> 0 | AO4: ='BIO DATA'!BG3 -> 0 | AP4: ='BIO DATA'!BH3 -> Mohammad Sanusi, S.H.I.
A5: A | B5: 14 | C5: ='BIO DATA'!#REF! -> #REF! | D5: ='BIO DATA'!#REF! -> #REF! | E5: ='BIO DATA'!#REF! -> #REF! | F5: ='BIO DATA'!#REF! -> #REF! | G5: ='BIO DATA'!#REF! -> #REF! | H5: ='BIO DATA'!#REF! -> #REF! | I5: ='BIO DATA'!#REF! -> #REF! | J5: ='BIO DATA'!#REF! -> #REF! | ... AP5: ='BIO DATA'!#REF! -> #REF!
A6: A | B6: 38 | C6: ='BIO DATA'!D4 -> 11589 | D6: ='BIO DATA'!E4 -> 3111141420 | E6: ='BIO DATA'!F4 -> Fahma Akhsananda Hidayat | F6: ='BIO DATA'!M4 -> Laki-laki | G6: ='BIO DATA'!N4 -> Cilacap | H6: ='BIO DATA'!P4 -> 40659 | I6: ='BIO DATA'!S4 -> Islam | J6: ='BIO DATA'!J4 -> 3 | K6: ='BIO DATA'!K4 -> 2 | L6: ='BIO DATA'!T4 -> Jl. Hadiwisastro RT 004 RW 002 Pesawahan Binangun Cilacap Jawa Tengah 53281 | M6: ='BIO DATA'!V4 -> Pesawahan | N6: ='BIO DATA'!W4 -> Binangun | O6: ='BIO DATA'!X4 -> Cilacap | P6: ='BIO DATA'!Y4 -> Jawa Tengah | Q6: ='BIO DATA'!Z4 -> MTs Mu'allimin Muh Yogyakarta | R6: ='BIO DATA'!AA4 -> Jalan Suroto 5 Padukuhan Jl. Gn. Bulu, Bandut Lor, Argorejo, Kec. Sedayu, Kabupaten Bantul, Daerah Istimewa Yogyakarta 55756 | S6: ='BIO DATA'!AB4 -> 0 | T6: ='BIO DATA'!AC4 -> Nur Hidayat, S.Ag. | ... AG6: ='BIO DATA'!AP4 -> 0 | AH6: ='BIO DATA'!AZ4 -> 0 | AI6: ='BIO DATA'!BA4 -> Islam | AJ6: ='BIO DATA'!BB4 -> 0 | AK6: ='BIO DATA'!BC4 -> 0 | AL6: ='BIO DATA'!BD4 -> 0 | AM6: ='BIO DATA'!BE4 -> 0 | AN6: ='BIO DATA'!BF4 -> 0 | AO6: ='BIO DATA'!BG4 -> 0 | AP6: ='BIO DATA'!BH4 -> Mohammad Sanusi, S.H.I.
A7: A | B7: 40 | C7: ='BIO DATA'!D5 -> 11607 | D7: ='BIO DATA'!E5 -> 010502043 | E7: ='BIO DATA'!F5 -> Feris Lutfi Hilal Mahadi | F7: ='BIO DATA'!M5 -> Laki-laki | G7: ='BIO DATA'!N5 -> Magelang | H7: ='BIO DATA'!P5 -> 40490 | I7: ='BIO DATA'!S5 -> Islam | J7: ='BIO DATA'!J5 -> 1 | K7: ='BIO DATA'!K5 -> 1 | L7: ='BIO DATA'!T5 -> Mergangsan Lor MG II/1098 YK RT 045 RW 014 Wirogunan Mergangsan Kota Yogyakarta DIY 55151 | M7: ='BIO DATA'!V5 -> Wirogunan | N7: ='BIO DATA'!W5 -> Mergangsan | O7: ='BIO DATA'!X5 -> Kota Yogyakarta | P7: ='BIO DATA'!Y5 -> DI Yogyakarta | Q7: ='BIO DATA'!Z5 -> MTs Mu'allimin Muh Yogyakarta | R7: ='BIO DATA'!AA5 -> Jalan Suroto 5 Padukuhan Jl. Gn. Bulu, Bandut Lor, Argorejo, Kec. Sedayu, Kabupaten Bantul, Daerah Istimewa Yogyakarta 55757 | S7: ='BIO DATA'!AB5 -> 0 | T7: ='BIO DATA'!AC5 -> Samsu Hartanto | ... AG7: ='BIO DATA'!AP5 -> 0 | AH7: ='BIO DATA'!AZ5 -> 0 | AI7: ='BIO DATA'!BA5 -> Islam | AJ7: ='BIO DATA'!BB5 -> 0 | AK7: ='BIO DATA'!BC5 -> 0 | AL7: ='BIO DATA'!BD5 -> 0 | AM7: ='BIO DATA'!BE5 -> 0 | AN7: ='BIO DATA'!BF5 -> 0 | AO7: ='BIO DATA'!BG5 -> 0 | AP7: ='BIO DATA'!BH5 -> Mohammad Sanusi, S.H.I.
A8: A | B8: 64 | C8: ='BIO DATA'!D6 -> 11608 | D8: ='BIO DATA'!E6 -> 3112084736 | E8: ='BIO DATA'!F6 -> Firaz Tsaqeffano | F8: ='BIO DATA'!M6 -> Laki-laki | G8: ='BIO DATA'!N6 -> Banyumas | H8: ='BIO DATA'!P6 -> 40736 | I8: ='BIO DATA'!S6 -> Islam | J8: ='BIO DATA'!J6 -> 2 | K8: ='BIO DATA'!K6 -> 2 | L8: ='BIO DATA'!T6 -> Perumahan Pabuaran Indah no 24 Grendeng Purwokerto Utara Banyumas Jawa Tengah 53122 | M8: ='BIO DATA'!V6 -> Grendeng | N8: ='BIO DATA'!W6 -> Purwokerto Utara | O8: ='BIO DATA'!X6 -> Banyumas | P8: ='BIO DATA'!Y6 -> Jawa Tengah | Q8: ='BIO DATA'!Z6 -> MTs Mu'allimin Muh Yogyakarta | R8: ='BIO DATA'!AA6 -> Jalan Suroto 5 Padukuhan Jl. Gn. Bulu, Bandut Lor, Argorejo, Kec. Sedayu, Kabupaten Bantul, Daerah Istimewa Yogyakarta 55758 | S8: ='BIO DATA'!AB6 -> 0 | T8: ='BIO DATA'!AC6 -> Prastowo Tri Witono | ... AG8: ='BIO DATA'!AP6 -> 0 | AH8: ='BIO DATA'!AZ6 -> Franky Yoga Anggara | AI8: ='BIO DATA'!BA6 -> Islam | AJ8: ='BIO DATA'!BB6 -> SMA | AK8: ='BIO DATA'!BC6 -> Perangkat Desa | AL8: ='BIO DATA'!BD6 -> Jaten RT 01 Sendangsari Pajangan Bantul DIY | AM8: ='BIO DATA'!BE6 -> 0 | AN8: ='BIO DATA'!BF6 -> 0 | AO8: ='BIO DATA'!BG6 -> 0 | AP8: ='BIO DATA'!BH6 -> Mohammad Sanusi, S.H.I.
A9: A | B9: 88 | C9: ='BIO DATA'!D7 -> 11609 | D9: ='BIO DATA'!E7 -> 0111152815 | E9: ='BIO DATA'!F7 -> Fuad Imtiyaz Mubarok | F9: ='BIO DATA'!M7 -> Laki-laki | G9: ='BIO DATA'!N7 -> Jakarta | H9: ='BIO DATA'!P7 -> 40604 | I9: ='BIO DATA'!S7 -> Islam | J9: ='BIO DATA'!J7 -> 1 | K9: ='BIO DATA'!K7 -> 2 | L9: ='BIO DATA'!T7 -> Jalan Basuki No. 2G R T 006 RW 006 Cilangkap Cipayung Jakarta Timur DKI Jakarta 13870 | M9: ='BIO DATA'!V7 -> Cilangkap | N9: ='BIO DATA'!W7 -> Cipayung | O9: ='BIO DATA'!X7 -> Jakarta Timur | P9: ='BIO DATA'!Y7 -> DKI Jakarta | Q9: ='BIO DATA'!Z7 -> MTs Mu'allimin Muh Yogyakarta | R9: ='BIO DATA'!AA7 -> Jalan Suroto 5 Padukuhan Jl. Gn. Bulu, Bandut Lor, Argorejo, Kec. Sedayu, Kabupaten Bantul, Daerah Istimewa Yogyakarta 55759 | S9: ='BIO DATA'!AB7 -> 0 | T9: ='BIO DATA'!AC7 -> Achmad Mubarok | ... AG9: ='BIO DATA'!AP7 -> 0 | AH9: ='BIO DATA'!AZ7 -> 0 | AI9: ='BIO DATA'!BA7 -> Islam | AJ9: ='BIO DATA'!BB7 -> 0 | AK9: ='BIO DATA'!BC7 -> 0 | AL9: ='BIO DATA'!BD7 -> 0 | AM9: ='BIO DATA'!BE7 -> 0 | AN9: ='BIO DATA'!BF7 -> 0 | AO9: ='BIO DATA'!BG7 -> 0 | AP9: ='BIO DATA'!BH7 -> Mohammad Sanusi, S.H.I.
A10: A | B10: 90 | C10: ='BIO DATA'!D8 -> 11616 | D10: ='BIO DATA'!E8 -> 0112858971 | E10: ='BIO DATA'!F8 -> Habiburrahman Al Azizi | F10: ='BIO DATA'!M8 -> Laki-laki | G10: ='BIO DATA'!N8 -> Boyolali | H10: ='BIO DATA'!P8 -> 40572 | I10: ='BIO DATA'!S8 -> Islam | J10: ='BIO DATA'!J8 -> 1 | K10: ='BIO DATA'!K8 -> 1 | L10: ='BIO DATA'!T8 -> Dk VII Dukuh Puron RT 048 Trimurti Srandakan Bantul DIY 55762 | M10: ='BIO DATA'!V8 -> Trimurti | N10: ='BIO DATA'!W8 -> Srandakan | O10: ='BIO DATA'!X8 -> Bantul | P10: ='BIO DATA'!Y8 -> DI Yogyakarta | Q10: ='BIO DATA'!Z8 -> MTs Mu'allimin Muh Yogyakarta | R10: ='BIO DATA'!AA8 -> Jalan Suroto 5 Padukuhan Jl. Gn. Bulu, Bandut Lor, Argorejo, Kec. Sedayu, Kabupaten Bantul, Daerah Istimewa Yogyakarta 55760 | S10: ='BIO DATA'!AB8 -> 0 | T10: ='BIO DATA'!AC8 -> (Alm.) Abdul Razaq | ... AG10: ='BIO DATA'!AP8 -> 0 | AH10: ='BIO DATA'!AZ8 -> 0 | AI10: ='BIO DATA'!BA8 -> Islam | AJ10: ='BIO DATA'!BB8 -> 0 | AK10: ='BIO DATA'!BC8 -> 0 | AL10: ='BIO DATA'!BD8 -> 0 | AM10: ='BIO DATA'!BE8 -> 0 | AN10: ='BIO DATA'!BF8 -> 0 | AO10: ='BIO DATA'!BG8 -> 0 | AP10: ='BIO DATA'!BH8 -> Mohammad Sanusi, S.H.I.
A11: A | B11: 93 | C11: ='BIO DATA'!D9 -> 11624 | D11: ='BIO DATA'!E9 -> 0112825165 | E11: ='BIO DATA'!F9 -> Hail Kaisan Izzati | F11: ='BIO DATA'!M9 -> Laki-laki | G11: ='BIO DATA'!N9 -> Cilacap | H11: ='BIO DATA'!P9 -> 40743 | I11: ='BIO DATA'!S9 -> Islam | J11: ='BIO DATA'!J9 -> 1 | K11: ='BIO DATA'!K9 -> 2 | L11: ='BIO DATA'!T9 -> Jenang RT 003/019 Majenang Cilacap Jawa Tengah 53257 | M11: ='BIO DATA'!V9 -> Jenang | N11: ='BIO DATA'!W9 -> Majenang | O11: ='BIO DATA'!X9 -> Cilacap | P11: ='BIO DATA'!Y9 -> Jawa Tengah | Q11: ='BIO DATA'!Z9 -> MTs Mu'allimin Muh Yogyakarta | R11: ='BIO DATA'!AA9 -> Jalan Suroto 5 Padukuhan Jl. Gn. Bulu, Bandut Lor, Argorejo, Kec. Sedayu, Kabupaten Bantul, Daerah Istimewa Yogyakarta 55761 | S11: ='BIO DATA'!AB9 -> 0 | T11: ='BIO DATA'!AC9 -> Arif Budi Santosa | ... AG11: ='BIO DATA'!AP9 -> 0 | AH11: ='BIO DATA'!AZ9 -> 0 | AI11: ='BIO DATA'!BA9 -> Islam | AJ11: ='BIO DATA'!BB9 -> 0 | AK11: ='BIO DATA'!BC9 -> 0 | AL11: ='BIO DATA'!BD9 -> 0 | AM11: ='BIO DATA'!BE9 -> 0 | AN11: ='BIO DATA'!BF9 -> 0 | AO11: ='BIO DATA'!BG9 -> 0 | AP11: ='BIO DATA'!BH9 -> Mohammad Sanusi, S.H.I.
A12: A | B12: 96 | C12: ='BIO DATA'!D10 -> 11625 | D12: ='BIO DATA'!E10 -> 0112205063 | E12: ='BIO DATA'!F10 -> Haiz Elhaq Rahman | F12: ='BIO DATA'!M10 -> Laki-laki | G12: ='BIO DATA'!N10 -> Cairo | H12: ='BIO DATA'!P10 -> 40736 | I12: ='BIO DATA'!S10 -> Islam | J12: ='BIO DATA'!J10 -> 3 | K12: ='BIO DATA'!K10 -> 5 | L12: ='BIO DATA'!T10 -> Jl. Caringin Komplek Fizhilala Al Quran RT 004 RW 012 Sayang Jatinangor Sumedang Jawa Barat 45363 | M12: ='BIO DATA'!V10 -> Sayang | N12: ='BIO DATA'!W10 -> Jatinangor | O12: ='BIO DATA'!X10 -> Sumedang | P12: ='BIO DATA'!Y10 -> Jawa Barat | Q12: ='BIO DATA'!Z10 -> MTs Mu'allimin Muh Yogyakarta | R12: ='BIO DATA'!AA10 -> Jalan Suroto 5 Padukuhan Jl. Gn. Bulu, Bandut Lor, Argorejo, Kec. Sedayu, Kabupaten Bantul, Daerah Istimewa Yogyakarta 55762 | S12: ='BIO DATA'!AB10 -> 0 | T12: ='BIO DATA'!AC10 -> Cecep Taufikurrohman | ... AG12: ='BIO DATA'!AP10 -> 0 | AH12: ='BIO DATA'!AZ10 -> 0 | AI12: ='BIO DATA'!BA10 -> Islam | AJ12: ='BIO DATA'!BB10 -> 0 | AK12: ='BIO DATA'!BC10 -> 0 | AL12: ='BIO DATA'!BD10 -> 0 | AM12: ='BIO DATA'!BE10 -> 0 | AN12: ='BIO DATA'!BF10 -> 0 | AO12: ='BIO DATA'!BG10 -> 0 | AP12: ='BIO DATA'!BH10 -> Mohammad Sanusi, S.H.I.
A13: A | B13: 110 | C13: ='BIO DATA'!D12 -> 11660 | D13: ='BIO DATA'!E12 -> 0109202081 | E13: ='BIO DATA'!F12 -> M.Dafa Wafiqul Azhar | F13: ='BIO DATA'!M12 -> Laki-laki | G13: ='BIO DATA'!N12 -> Lamongan | H13: ='BIO DATA'!P12 -> 40284 | I13: ='BIO DATA'!S12 -> Islam | J13: ='BIO DATA'!J12 -> 1 | K13: ='BIO DATA'!K12 -> 1 | L13: ='BIO DATA'!T12 -> Dsn. Bancak Wetan RT 001 RW 010 Krogowanan Sawangan Magelang Jawa Tengah 55481 | M13: ='BIO DATA'!V12 -> Krogowanan | N13: ='BIO DATA'!W12 -> Sawangan | O13: ='BIO DATA'!X12 -> Magelang | P13: ='BIO DATA'!Y12 -> Jawa Tengah | Q13: ='BIO DATA'!Z12 -> MTs Mu'allimin Muh Yogyakarta | R13: ='BIO DATA'!AA12 -> Jalan Suroto 5 Padukuhan Jl. Gn. Bulu, Bandut Lor, Argorejo, Kec. Sedayu, Kabupaten Bantul, Daerah Istimewa Yogyakarta 55764 | S13: ='BIO DATA'!AB12 -> 0 | T13: ='BIO DATA'!AC12 -> Anwarudin | ... AG13: ='BIO DATA'!AP12 -> 0 | AH13: ='BIO DATA'!AZ12 -> 0 | AI13: ='BIO DATA'!BA12 -> Islam | AJ13: ='BIO DATA'!BB12 -> 0 | AK13: ='BIO DATA'!BC12 -> 0 | AL13: ='BIO DATA'!BD12 -> 0 | AM13: ='BIO DATA'!BE12 -> 0 | AN13: ='BIO DATA'!BF12 -> 0 | AO13: ='BIO DATA'!BG12 -> 0 | AP13: ='BIO DATA'!BH12 -> Mohammad Sanusi, S.H.I.
A14: A | B14: 119 | C14: ='BIO DATA'!#REF! -> #REF! | D14: ='BIO DATA'!#REF! -> #REF! | E14: ='BIO DATA'!#REF! -> #REF! | F14: ='BIO DATA'!#REF! -> #REF! | G14: ='BIO DATA'!#REF! -> #REF! | H14: ='BIO DATA'!#REF! -> #REF! | I14: ='BIO DATA'!#REF! -> #REF! | J14: ='BIO DATA'!#REF! -> #REF! | ... AP14: ='BIO DATA'!#REF! -> #REF!
A15: A | B15: 128 | C15: ='BIO DATA'!D13 -> 11677 | D15: ='BIO DATA'!E13 -> 0104224489 | E15: ='BIO DATA'!F13 -> Muhamad Azriel Akbar Setya Putra | F15: ='BIO DATA'!M13 -> Laki-laki | G15: ='BIO DATA'!N13 -> Grobogan | H15: ='BIO DATA'!P13 -> 40468 | I15: ='BIO DATA'!S13 -> Islam | J15: ='BIO DATA'!J13 -> 1 | K15: ='BIO DATA'!K13 -> 1 | L15: ='BIO DATA'!T13 -> Getaspejaten RT 010 RW 004 Jati Kudus Jawa Tengah 59343 | M15: ='BIO DATA'!V13 -> Getaspejaten | N15: ='BIO DATA'!W13 -> Jati | O15: ='BIO DATA'!X13 -> Kudus | P15: ='BIO DATA'!Y13 -> Jawa Tengah | Q15: ='BIO DATA'!Z13 -> MTs Mu'allimin Muh Yogyakarta | R15: ='BIO DATA'!AA13 -> Jalan Suroto 5 Padukuhan Jl. Gn. Bulu, Bandut Lor, Argorejo, Kec. Sedayu, Kabupaten Bantul, Daerah Istimewa Yogyakarta 55766 | S15: ='BIO DATA'!AB13 -> 0 | T15: ='BIO DATA'!AC13 -> Iwan Setiawan | ... AG15: ='BIO DATA'!AP13 -> 0 | AH15: ='BIO DATA'!AZ13 -> 0 | AI15: ='BIO DATA'!BA13 -> Islam | AJ15: ='BIO DATA'!BB13 -> 0 | AK15: ='BIO DATA'!BC13 -> 0 | AL15: ='BIO DATA'!BD13 -> 0 | AM15: ='BIO DATA'!BE13 -> 0 | AN15: ='BIO DATA'!BF13 -> 0 | AO15: ='BIO DATA'!BG13 -> 0 | AP15: ='BIO DATA'!BH13 -> Mohammad Sanusi, S.H.I.
A16: A | B16: 130 | C16: ='BIO DATA'!D14 -> 11678 | D16: ='BIO DATA'!E14 -> 3119592992 | E16: ='BIO DATA'!F14 -> Muhammad Abid Al Dzaka | F16: ='BIO DATA'!M14 -> Laki-laki | G16: ='BIO DATA'!N14 -> Sleman | H16: ='BIO DATA'!P14 -> 39502 | I16: ='BIO DATA'!S14 -> Islam | J16: ='BIO DATA'!J14 -> 2 | K16: ='BIO DATA'!K14 -> 3 | L16: ='BIO DATA'!T14 -> Babadan IV RT 003 RW 009 Sendangagung Minggir Sleman DIY 55562 | M16: ='BIO DATA'!V14 -> Sendangagung | N16: ='BIO DATA'!W14 -> Minggir | O16: ='BIO DATA'!X14 -> Sleman | P16: ='BIO DATA'!Y14 -> DI Yogyakarta | Q16: ='BIO DATA'!Z14 -> MTs Mu'allimin Muh Yogyakarta | R16: ='BIO DATA'!AA14 -> Jalan Suroto 5 Padukuhan Jl. Gn. Bulu, Bandut Lor, Argorejo, Kec. Sedayu, Kabupaten Bantul, Daerah Istimewa Yogyakarta 55767 | S16: ='BIO DATA'!AB14 -> 0 | T16: ='BIO DATA'!AC14 -> Indra Mulyani | ... AG16: ='BIO DATA'!AP14 -> 0 | AH16: ='BIO DATA'!AZ14 -> 0 | AI16: ='BIO DATA'!BA14 -> Islam | AJ16: ='BIO DATA'!BB14 -> 0 | AK16: ='BIO DATA'!BC14 -> 0 | AL16: ='BIO DATA'!BD14 -> 0 | AM16: ='BIO DATA'!BE14 -> 0 | AN16: ='BIO DATA'!BF14 -> 0 | AO16: ='BIO DATA'!BG14 -> 0 | AP16: ='BIO DATA'!BH14 -> Mohammad Sanusi, S.H.I.
A17: A | B17: 141 | C17: ='BIO DATA'!D15 -> 11659 | D17: ='BIO DATA'!E15 -> 0103157116 | E17: ='BIO DATA'!F15 -> M. Abyan Qisthi Nabhani | F17: ='BIO DATA'!M15 -> Laki-laki | G17: ='BIO DATA'!N15 -> Pekalongan | H17: ='BIO DATA'!P15 -> 40518 | I17: ='BIO DATA'!S15 -> Islam | J17: ='BIO DATA'!J15 -> 1 | K17: ='BIO DATA'!K15 -> 2 | L17: ='BIO DATA'!T15 -> Podo Gg. 2B RT 011 RW 002 Kedungwuni Pekalongan Jawa Tengah 51173 | M17: ='BIO DATA'!V15 -> Podo | N17: ='BIO DATA'!W15 -> Kedungwuni | O17: ='BIO DATA'!X15 -> Pekalongan | P17: ='BIO DATA'!Y15 -> Jawa Tengah | Q17: ='BIO DATA'!Z15 -> MTs Mu'allimin Muh Yogyakarta | R17: ='BIO DATA'!AA15 -> Jalan Suroto 5 Padukuhan Jl. Gn. Bulu, Bandut Lor, Argorejo, Kec. Sedayu, Kabupaten Bantul, Daerah Istimewa Yogyakarta 55768 | S17: ='BIO DATA'!AB15 -> 0 | T17: ='BIO DATA'!AC15 -> Muh. Bakrin | ... AG17: ='BIO DATA'!AP15 -> 0 | AH17: ='BIO DATA'!AZ15 -> 0 | AI17: ='BIO DATA'!BA15 -> Islam | AJ17: ='BIO DATA'!BB15 -> 0 | AK17: ='BIO DATA'!BC15 -> 0 | AL17: ='BIO DATA'!BD15 -> 0 | AM17: ='BIO DATA'!BE15 -> 0 | AN17: ='BIO DATA'!BF15 -> 0 | AO17: ='BIO DATA'!BG15 -> 0 | AP17: ='BIO DATA'!BH15 -> Mohammad Sanusi, S.H.I.
A18: A | B18: 157 | C18: ='BIO DATA'!D16 -> 11687 | D18: ='BIO DATA'!E16 -> 0118383409 | E18: ='BIO DATA'!F16 -> Muhammad Almairi Akhyar | F18: ='BIO DATA'!M16 -> Laki-laki | G18: ='BIO DATA'!N16 -> Manggar | H18: ='BIO DATA'!P16 -> 40840 | I18: ='BIO DATA'!S16 -> Islam | J18: ='BIO DATA'!J16 -> 2 | K18: ='BIO DATA'!K16 -> 2 | L18: ='BIO DATA'!T16 -> Dsn. Padang II RT 008 RW 004 Padang Manggar Belitung Timur Kepulauan Bangka Belitung 33516 | M18: ='BIO DATA'!V16 -> Padang | N18: ='BIO DATA'!W16 -> Manggar | O18: ='BIO DATA'!X16 -> Belitung Timur | P18: ='BIO DATA'!Y16 -> Kepulauan Bangka Belitung | Q18: ='BIO DATA'!Z16 -> MTs Mu'allimin Muh Yogyakarta | R18: ='BIO DATA'!AA16 -> Jalan Suroto 5 Padukuhan Jl. Gn. Bulu, Bandut Lor, Argorejo, Kec. Sedayu, Kabupaten Bantul, Daerah Istimewa Yogyakarta 55769 | S18: ='BIO DATA'!AB16 -> 0 | T18: ='BIO DATA'!AC16 -> Agustian | ... AG18: ='BIO DATA'!AP16 -> 0 | AH18: ='BIO DATA'!AZ16 -> 0 | AI18: ='BIO DATA'!BA16 -> Islam | AJ18: ='BIO DATA'!BB16 -> 0 | AK18: ='BIO DATA'!BC16 -> 0 | AL18: ='BIO DATA'!BD16 -> 0 | AM18: ='BIO DATA'!BE16 -> 0 | AN18: ='BIO DATA'!BF16 -> 0 | AO18: ='BIO DATA'!BG16 -> 0 | AP18: ='BIO DATA'!BH16 -> Mohammad Sanusi, S.H.I.
A19: A | B19: 159 | C19: ='BIO DATA'!D17 -> 11699 | D19: ='BIO DATA'!E17 -> 0114574227 | E19: ='BIO DATA'!F17 -> Muhammad Burhanuddin Robbani | F19: ='BIO DATA'!M17 -> Laki-laki | G19: ='BIO DATA'!N17 -> Jakarta | H19: ='BIO DATA'!P17 -> 40617 | I19: ='BIO DATA'!S17 -> Islam | J19: ='BIO DATA'!J17 -> 2 | K19: ='BIO DATA'!K17 -> 2 | L19: ='BIO DATA'!T17 -> Srengseng No 2 RT 002 RW 002 Srengseng Kembangan Jakarta Barat DKI Jakarta 11630 | M19: ='BIO DATA'!V17 -> Srengseng | N19: ='BIO DATA'!W17 -> Kembangan | O19: ='BIO DATA'!X17 -> Jakarta Barat | P19: ='BIO DATA'!Y17 -> DKI Jakarta | Q19: ='BIO DATA'!Z17 -> MTs Mu'allimin Muh Yogyakarta | R19: ='BIO DATA'!AA17 -> Jalan Suroto 5 Padukuhan Jl. Gn. Bulu, Bandut Lor, Argorejo, Kec. Sedayu, Kabupaten Bantul, Daerah Istimewa Yogyakarta 55770 | S19: ='BIO DATA'!AB17 -> 0 | T19: ='BIO DATA'!AC17 -> Nurhadi | ... AG19: ='BIO DATA'!AP17 -> 0 | AH19: ='BIO DATA'!AZ17 -> 0 | AI19: ='BIO DATA'!BA17 -> Islam | AJ19: ='BIO DATA'!BB17 -> 0 | AK19: ='BIO DATA'!BC17 -> 0 | AL19: ='BIO DATA'!BD17 -> 0 | AM19: ='BIO DATA'!BE17 -> 0 | AN19: ='BIO DATA'!BF17 -> 0 | AO19: ='BIO DATA'!BG17 -> 0 | AP19: ='BIO DATA'!BH17 -> Mohammad Sanusi, S.H.I.
A20: A | B20: 171 | C20: ='BIO DATA'!D18 -> 11701 | D20: ='BIO DATA'!E18 -> 0116953353 | E20: ='BIO DATA'!F18 -> Muhammad Dwilutfan Ahda | F20: ='BIO DATA'!M18 -> Laki-laki | G20: ='BIO DATA'!N18 -> Belitung | H20: ='BIO DATA'!P18 -> 40836 | I20: ='BIO DATA'!S18 -> Islam | J20: ='BIO DATA'!J18 -> 2 | K20: ='BIO DATA'!K18 -> 4 | L20: ='BIO DATA'!T18 -> Dsn. Pancur I RT 001 RW 001 Padang Manggar Belitung Timur Kepulauan Bangka Belitung 33516 | M20: ='BIO DATA'!V18 -> Padang | N20: ='BIO DATA'!W18 -> Manggar | O20: ='BIO DATA'!X18 -> Belitung Timur | P20: ='BIO DATA'!Y18 -> Kepulauan Bangka Belitung | Q20: ='BIO DATA'!Z18 -> MTs Mu'allimin Muh Yogyakarta | R20: ='BIO DATA'!AA18 -> Jalan Suroto 5 Padukuhan Jl. Gn. Bulu, Bandut Lor, Argorejo, Kec. Sedayu, Kabupaten Bantul, Daerah Istimewa Yogyakarta 55771 | S20: ='BIO DATA'!AB18 -> 0 | T20: ='BIO DATA'!AC18 -> Samlawi | ... AG20: ='BIO DATA'!AP18 -> 0 | AH20: ='BIO DATA'!AZ18 -> 0 | AI20: ='BIO DATA'!BA18 -> Islam | AJ20: ='BIO DATA'!BB18 -> 0 | AK20: ='BIO DATA'!BC18 -> 0 | AL20: ='BIO DATA'!BD18 -> 0 | AM20: ='BIO DATA'!BE18 -> 0 | AN20: ='BIO DATA'!BF18 -> 0 | AO20: ='BIO DATA'!BG18 -> 0 | AP20: ='BIO DATA'!BH18 -> Mohammad Sanusi, S.H.I.
A21: A | B21: 177 | C21: ='BIO DATA'!#REF! -> #REF! | D21: ='BIO DATA'!#REF! -> #REF! | E21: ='BIO DATA'!#REF! -> #REF! | F21: ='BIO DATA'!#REF! -> #REF! | G21: ='BIO DATA'!#REF! -> #REF! | H21: ='BIO DATA'!#REF! -> #REF! | I21: ='BIO DATA'!#REF! -> #REF! | J21: ='BIO DATA'!#REF! -> #REF! | ... AP21: ='BIO DATA'!#REF! -> #REF!
A22: A | B22: 192 | C22: ='BIO DATA'!#REF! -> #REF! | D22: ='BIO DATA'!#REF! -> #REF! | E22: ='BIO DATA'!#REF! -> #REF! | F22: ='BIO DATA'!#REF! -> #REF! | G22: ='BIO DATA'!#REF! -> #REF! | H22: ='BIO DATA'!#REF! -> #REF! | I22: ='BIO DATA'!#REF! -> #REF! | J22: ='BIO DATA'!#REF! -> #REF! | ... AP22: ='BIO DATA'!#REF! -> #REF!
A23: A | B23: 202 | C23: ='BIO DATA'!D19 -> 11722 | D23: ='BIO DATA'!E19 -> 0112036009 | E23: ='BIO DATA'!F19 -> Muhammad Ibra Bekti Rohmadhoni | F23: ='BIO DATA'!M19 -> Laki-laki | G23: ='BIO DATA'!N19 -> Bojonegoro | H23: ='BIO DATA'!P19 -> 40759 | I23: ='BIO DATA'!S19 -> Islam | J23: ='BIO DATA'!J19 -> 1 | K23: ='BIO DATA'!K19 -> 1 | L23: ='BIO DATA'!T19 -> Jl. Muh. Husni Thamrin RT 001 RW 002 Tomba Wolio Kota Baubau Sulawesi Tenggara 93712 | M23: ='BIO DATA'!V19 -> Tomba | N23: ='BIO DATA'!W19 -> Wolio | O23: ='BIO DATA'!X19 -> Kota Baubau | P23: ='BIO DATA'!Y19 -> Sulawesi Tenggara | Q23: ='BIO DATA'!Z19 -> MTs Mu'allimin Muh Yogyakarta | R23: ='BIO DATA'!AA19 -> Jalan Suroto 5 Padukuhan Jl. Gn. Bulu, Bandut Lor, Argorejo, Kec. Sedayu, Kabupaten Bantul, Daerah Istimewa Yogyakarta 55774 | S23: ='BIO DATA'!AB19 -> 0 | T23: ='BIO DATA'!AC19 -> Imam Subekti | ... AG23: ='BIO DATA'!AP19 -> 0 | AH23: ='BIO DATA'!AZ19 -> 0 | AI23: ='BIO DATA'!BA19 -> Islam | AJ23: ='BIO DATA'!BB19 -> 0 | AK23: ='BIO DATA'!BC19 -> 0 | AL23: ='BIO DATA'!BD19 -> 0 | AM23: ='BIO DATA'!BE19 -> 0 | AN23: ='BIO DATA'!BF19 -> 0 | AO23: ='BIO DATA'!BG19 -> 0 | AP23: ='BIO DATA'!BH19 -> Mohammad Sanusi, S.H.I.
A24: A | B24: 211 | C24: ='BIO DATA'!D20 -> 11728 | D24: ='BIO DATA'!E20 -> 0109802442 | E24: ='BIO DATA'!F20 -> Muhammad Naufal Rasyiid Jaya | F24: ='BIO DATA'!M20 -> Laki-laki | G24: ='BIO DATA'!N20 -> Sleman | H24: ='BIO DATA'!P20 -> 40373 | I24: ='BIO DATA'!S20 -> Islam | J24: ='BIO DATA'!J20 -> 1 | K24: ='BIO DATA'!K20 -> 1 | L24: ='BIO DATA'!T20 -> Bodeh RT 001 RW 023 Ambarketawang Gamping Sleman DIY 55294 | M24: ='BIO DATA'!V20 -> Ambarketawang | N24: ='BIO DATA'!W20 -> Gamping | O24: ='BIO DATA'!X20 -> Sleman | P24: ='BIO DATA'!Y20 -> DI Yogyakarta | Q24: ='BIO DATA'!Z20 -> MTs Mu'allimin Muh Yogyakarta | R24: ='BIO DATA'!AA20 -> Jalan Suroto 5 Padukuhan Jl. Gn. Bulu, Bandut Lor, Argorejo, Kec. Sedayu, Kabupaten Bantul, Daerah Istimewa Yogyakarta 55775 | S24: ='BIO DATA'!AB20 -> 0 | T24: ='BIO DATA'!AC20 -> Supangat Infantri Jaya | ... AG24: ='BIO DATA'!AP20 -> 0 | AH24: ='BIO DATA'!AZ20 -> 0 | AI24: ='BIO DATA'!BA20 -> Islam | AJ24: ='BIO DATA'!BB20 -> 0 | AK24: ='BIO DATA'!BC20 -> 0 | AL24: ='BIO DATA'!BD20 -> 0 | AM24: ='BIO DATA'!BE20 -> 0 | AN24: ='BIO DATA'!BF20 -> 0 | AO24: ='BIO DATA'!BG20 -> 0 | AP24: ='BIO DATA'!BH20 -> Mohammad Sanusi, S.H.I.
A25: A | B25: 227 | C25: ='BIO DATA'!D21 -> 11731 | D25: ='BIO DATA'!E21 -> 3103569331 | E25: ='BIO DATA'!F21 -> Muhammad Rafa Arrayyan | F25: ='BIO DATA'!M21 -> Laki-laki | G25: ='BIO DATA'!N21 -> Jakarta | H25: ='BIO DATA'!P21 -> 40382 | I25: ='BIO DATA'!S21 -> Islam | J25: ='BIO DATA'!J21 -> 1 | K25: ='BIO DATA'!K21 -> 2 | L25: ='BIO DATA'!T21 -> Jl. Swadaya PLN Klender RT 003 RW 002 Jatinegara Cakung Jakarta Timur DKI Jakarta 13930 | M25: ='BIO DATA'!V21 -> Jatinegara | N25: ='BIO DATA'!W21 -> Cakung | O25: ='BIO DATA'!X21 -> Jakarta Timur | P25: ='BIO DATA'!Y21 -> DKI Jakarta | Q25: ='BIO DATA'!Z21 -> MTs Mu'allimin Muh Yogyakarta | R25: ='BIO DATA'!AA21 -> Jalan Suroto 5 Padukuhan Jl. Gn. Bulu, Bandut Lor, Argorejo, Kec. Sedayu, Kabupaten Bantul, Daerah Istimewa Yogyakarta 55776 | S25: ='BIO DATA'!AB21 -> 0 | T25: ='BIO DATA'!AC21 -> Trinanda Munfaji (alm.) | ... AG25: ='BIO DATA'!AP21 -> 0 | AH25: ='BIO DATA'!AZ21 -> 0 | AI25: ='BIO DATA'!BA21 -> Islam | AJ25: ='BIO DATA'!BB21 -> 0 | AK25: ='BIO DATA'!BC21 -> 0 | AL25: ='BIO DATA'!BD21 -> 0 | AM25: ='BIO DATA'!BE21 -> 0 | AN25: ='BIO DATA'!BF21 -> 0 | AO25: ='BIO DATA'!BG21 -> 0 | AP25: ='BIO DATA'!BH21 -> Mohammad Sanusi, S.H.I.
A26: A | B26: 268 | C26: ='BIO DATA'!D22 -> 11735 | D26: ='BIO DATA'!E22 -> 0119936984 | E26: ='BIO DATA'!F22 -> Muhammad Razan Al Azka Panglimunan | F26: ='BIO DATA'!M22 -> Laki-laki | G26: ='BIO DATA'!N22 -> Solo | H26: ='BIO DATA'!P22 -> 40694 | I26: ='BIO DATA'!S22 -> Islam | J26: ='BIO DATA'!J22 -> 1 | K26: ='BIO DATA'!K22 -> 1 | L26: ='BIO DATA'!T22 -> Jl. Sekar Jagad 1 No. 21A RT 004 RW 001 Pajang Laweyan Surakarta Jawa Tengah 57146 | M26: ='BIO DATA'!V22 -> Pajang | N26: ='BIO DATA'!W22 -> Laweyan | O26: ='BIO DATA'!X22 -> Kota Surakarta | P26: ='BIO DATA'!Y22 -> Jawa Tengah | Q26: ='BIO DATA'!Z22 -> MTs Mu'allimin Muh Yogyakarta | R26: ='BIO DATA'!AA22 -> Jalan Suroto 5 Padukuhan Jl. Gn. Bulu, Bandut Lor, Argorejo, Kec. Sedayu, Kabupaten Bantul, Daerah Istimewa Yogyakarta 55777 | S26: ='BIO DATA'!AB22 -> 0 | T26: ='BIO DATA'!AC22 -> Muhammad Iqbal | ... AG26: ='BIO DATA'!AP22 -> 0 | AH26: ='BIO DATA'!AZ22 -> 0 | AI26: ='BIO DATA'!BA22 -> Islam | AJ26: ='BIO DATA'!BB22 -> 0 | AK26: ='BIO DATA'!BC22 -> 0 | AL26: ='BIO DATA'!BD22 -> 0 | AM26: ='BIO DATA'!BE22 -> 0 | AN26: ='BIO DATA'!BF22 -> 0 | AO26: ='BIO DATA'!BG22 -> 0 | AP26: ='BIO DATA'!BH22 -> Mohammad Sanusi, S.H.I.
