Workbook

Sheet BIO DATA
A1: NO | B1: ASAL | C1: PARALEL | D1: NIS | E1: NISN | F1: NAMA SISWA | G1: TGL MASUK | H1: TAHUN IJAZAH | I1: NO IJAZAH | J1: Anak Ke | K1: Jml Saudara | L1: Nomor Pendaftaran | M1: Jenis Kelamin | N1: TEMPAT LAHIR | O1: TANGGAL LAHIR | P1: TANGGAL LAHIR1 | R1: NIK ANAK | S1: Agama | T1: ALAMAT | U1: KODE POS | V1: KELURAHAN | W1: KECAMATAN | X1: Kabupaten/kota | Y1: Provinsi | Z1: Asal Sekolah | AA1: Alamat Sekolah | AB1: Prestasi | AC1: Nama Ayah | AD1: Agama Ayah | AE1: Pendidikan | AF1: Pekerjaan | AG1: Penghasilan | AH1: Telp | AI1: Email | AJ1: Nama Ibu | AK1: Agama Ibu | AL1: Pendidikan | AM1: Pekerjaan1 | AN1: Penghasilan | AO1: Telp1 | AP1: Email | AQ1: KK | AR1: NIK AYAH | AS1: TEMPAT LAHIR AYAH | AT1: TGL LAHIR AYAH | AV1: NIK IBU | AW1: TEMPAT LAHIR IBU | AX1: TGL LAHIR IBU | AZ1: Nama Wali | BA1: Agama Wali | BB1: Pendidikan2 | BC1: Pekerjaan2 | BD1: Alamat Wali | BE1: Penghasilan2 | BF1: Telp2 | BG1: Email2 | BH1: Nama WK | BI1: NBM WK | BJ1: Nama Direktur | BK1: NBM/NIP.
A2: 1 | B2: G | C2: A | D2: 10886 | E2: 0082005792 | F2: Ahmad Abrisam Awaluddin Fadlur Rahman | G2: 10 Juli 2021 | H2: 2021 | J2: 1 | M2: Laki-laki | N2: Surabaya | O2: 39612 | P2: 13 Juni 2008 | S2: Islam | T2: Jl. Jemurwonosari Gang I No 16 B Wonocolo Surabaya Jawa Timur | U2: 60237 | V2: Jemursari | W2: Wonocolo | X2: Surabaya | Y2: Jawa Timur | Z2: MTs Mu'allimin Muh. Yogyakarta | AA2: Jl. Letjend. S. Parman No. 68 Yogyakarta | AC2: Mukhlasin, ST., M.Pd. | AD2: Islam | AE2: S2 | AF2: Guru | AH2: 08231838805 | AJ2: Luklu'ul Islamiyati | AK2: Islam | AL2: S1 | AM2: Guru | AO2: 081357567445 | BA2: Islam | BH2: Ikhwanuddin, S.H.I., M.S.I. | BI2: 861141 | BJ2: Dr. Mhd. Lailan Arqam, M.Pd. | BK2: - / 895 833
A3: 2 | B3: H | C3: A | D3: 10907 | E3: 0081641644 | F3: Arash Fardad Muhammad Fateh | G3: 10 Juli 2021 | H3: 2021 | J3: 1 | K3: 2 | M3: Laki-laki | N3: Magelang | O3: 39630 | P3: 01 Juli 2008 | R3: 3308080107080005 | S3: Islam | T3: Mingking Sokorini Muntilan Kab. Magelang Jawa Tengah 56451 | U3: 56451 | V3: Sokorini | W3: Muntilan | X3: Magelang | Y3: Jawa Tengah | Z3: MTs Mu'allimin Muh. Yogyakarta | AA3: Jl. Letjend. S. Parman No. 68 Yogyakarta | AC3: Ahmad Abdul Jabar | AD3: Islam | AE3: S1 | AF3: Wiraswasta | AH3: 081328054592 | AJ3: Lestari Ningsih | AK3: Islam | AL3: Diploma | AM3: Wiraswasta | AO3: 085867153432 | AQ3: 3308082010120038 | AR3: 3308081607740003 | AS3: Magelang | AT3: 27226 | AV3: 3308084804840003 | AW3: Magelang | AX3: 4/8/1884 | BA3: Islam | BH3: Ikhwanuddin, S.H.I., M.S.I. | BI3: 861142 | BJ3: H. Aly Aulia, Lc. M. Hum. | BK3: - / 865 966
A4: 3 | B4: D | C4: A | D4: 10908 | E4: 0089552731 | F4: Ardiansyah Rafi Ramadhan | G4: 10 Juli 2021 | H4: 2021 | J4: 1 | M4: Laki-laki | N4: Yogyakarta | O4: 39693 | P4: 02 September 2008 | S4: Islam | T4: Warungboto, Umbulharjo 4 RT 31 RW 08 No 868 Kota Yogyakarta DI Yogyakarta | U4: 55164 | V4: Warungboto | W4: Umbulharjo | X4: Kota Yogyakarta | Y4: DI Yogyakarta | Z4: MTs Mu'allimin Muh. Yogyakarta | AA4: Jl. Letjend. S. Parman No. 68 Yogyakarta | AC4: Muhammad Ma'ruf | AD4: Islam | AF4: Wiraswasta | AH4: 085225099962 | AJ4: Masni Djaapar Talu | AK4: Islam | AM4: Lainnya | AO4: 085225099962 | BA4: Islam | BH4: Ikhwanuddin, S.H.I., M.S.I. | BI4: 861143 | BJ4: H. Aly Aulia, Lc. M. Hum. | BK4: - / 865 966
A5: 4 | B5: H | C5: A | D5: 10930 | E5: 3081859596 | F5: Bagus Murtadha Ayyasy Putra Amin | G5: 10 Juli 2021 | H5: 2021 | J5: 4 | M5: Laki-laki | N5: Wonosobo | O5: 39690 | P5: 30 Agustus 2008 | S5: Islam | T5: Tuksari Kejajar Wonosobo Jawa Tengah | U5: 56314 | V5: Tuksari | W5: Kejajar | X5: Wonosobo | Y5: Jawa Tengah | Z5: MTs Mu'allimin Muh. Yogyakarta | AA5: Jl. Letjend. S. Parman No. 68 Yogyakarta | AC5: Aminudin | AD5: Islam | AF5: Wiraswasta | AH5: 081327491584 | AJ5: Isti Rofah | AK5: Islam | AM5: PNS | AO5: 081327491584 | BA5: Islam | BH5: Ikhwanuddin, S.H.I., M.S.I. | BI5: 861144 | BJ5: H. Aly Aulia, Lc. M. Hum. | BK5: - / 865 966
A6: 5 | B6: B | C6: A | D6: 10973 | E6: 0094471717 | F6: Fathurrahman Al-Mumtaz | G6: 10 Juli 2021 | H6: 2021 | J6: 2 | K6: 1 | M6: Laki-laki | N6: Semarang | O6: 39986 | P6: 22 Juni 2009 | S6: Islam | T6: Pedukuhan Senuko Sidoagung Godean Sleman DI Yogyakarta | U6: 55264 | V6: Sidoagung | W6: Godean | X6: Sleman | Y6: DI Yogyakarta | Z6: MTs Mu'allimin Muh. Yogyakarta | AA6: Jl. Letjend. S. Parman No. 68 Yogyakarta | AC6: H. Eva Kumala Pontas, ST | AD6: Islam | AE6: S1 | AF6: Wiraswasta | AG6: Rp. 2.000.000,- s/d Rp. 5.000.000,- | AH6: 081215951700 | AI6: tu2t_romadhon@yahoo.co.id | AJ6: Hj. Hastuti Ramadhana, SE., SH., MH | AK6: Islam | AL6: S2 | AM6: PNS | AN6: di atas Rp. 5.000.000,- | AO6: 081228100684 | AP6: hastuti.ramadhana20@gmail.com | AS6: Sragen | AT6: 27121 | AW6: Yogyakarta | AX6: 27292 | BA6: Islam | BH6: Ikhwanuddin, S.H.I., M.S.I. | BI6: 861145 | BJ6: H. Aly Aulia, Lc. M. Hum. | BK6: - / 865 966
A7: 6 | B7: H | C7: A | D7: 10975 | E7: 0091610526 | F7: Fatih Fazliansyah | G7: 10 Juli 2021 | H7: 2021 | J7: 1 | M7: Laki-laki | N7: Tangerang | O7: 39913 | P7: 10 April 2009 | S7: Islam | T7: Jl. Masjid Baiturrahman Porisgaga Baru Batu Ceper Tangerang Banten | U7: 15122 | V7: Porisgaga Baru | W7: Batu Ceper | X7: Tangerang | Y7: Banten | Z7: MTs Mu'allimin Muh. Yogyakarta | AA7: Jl. Letjend. S. Parman No. 68 Yogyakarta | AC7: Firmansyah | AD7: Islam | AF7: Wiraswasta | AH7: 083807281732 | AJ7: Nurkoyimah | AK7: Islam | AM7: Wiraswasta | AO7: 083899511744 | BA7: Islam | BH7: Ikhwanuddin, S.H.I., M.S.I. | BI7: 861146 | BJ7: H. Aly Aulia, Lc. M. Hum. | BK7: - / 865 966
A8: 7 | B8: D | C8: A | D8: 10986 | E8: 0081988453 | F8: Ghatfan Muhammad Attar | G8: 10 Juli 2021 | H8: 2021 | J8: 3 | K8: 2 | M8: Laki-laki | N8: Bekasi | O8: 39719 | P8: 28 September 2008 | R8: 3216062809080002 | S8: Islam | T8: Jl. Gambir Sawit No. 18B 042/011 Pandeyan Umbulharjo Kota Yogyakarta DIY 55161 | U8: 55161 | V8: Pandeyan | W8: Umbulharjo | X8: Kota Yogyakarta | Y8: DI Yogyakarta | Z8: MTs Mu'allimin Muh. Yogyakarta | AA8: Jl. Letjend. S. Parman No. 68 Yogyakarta | AC8: Bambang Margarita, A.Md. | AD8: Islam | AE8: Diploma | AF8: Lainnya | AH8: 087796959161 | AJ8: Ambar Herawati | AK8: Islam | AL8: S1 | AM8: PNS | AO8: 085927465293 | AQ8: 3471130311150004 | AV8: 3218066211740013 | AW8: Gunungkidul | AX8: 27355 | BA8: Islam | BH8: Ikhwanuddin, S.H.I., M.S.I. | BI8: 861147 | BJ8: H. Aly Aulia, Lc. M. Hum. | BK8: - / 865 966
A9: 8 | B9: G | C9: A | D9: 10989 | E9: 0092583854 | F9: Ghozi Yazid Rahman | G9: 10 Juli 2021 | H9: 2021 | J9: 2 | M9: Laki-laki | N9: Purworejo | O9: 39821 | P9: 08 Januari 2009 | S9: Islam | T9: Jl. Gatot Subroto No. 461 Keseneng Purworejo Jawa Tengah | U9: 54181 | V9: Keseneng | W9: Purworejo | X9: Purworejo | Y9: Jawa Tengah | Z9: MTs Mu'allimin Muh. Yogyakarta | AA9: Jl. Letjend. S. Parman No. 68 Yogyakarta | AC9: Bakhruni Rakhman | AD9: Islam | AF9: Lainnya | AH9: 08122725844 | AJ9: Yulia Kurniawati | AK9: Islam | AM9: Lainnya | AO9: 081227851780 | BA9: Islam | BH9: Ikhwanuddin, S.H.I., M.S.I. | BI9: 861148 | BJ9: H. Aly Aulia, Lc. M. Hum. | BK9: - / 865 966
A10: 9 | B10: F | C10: A | D10: 10997 | E10: 0094445811 | F10: Hibban Ammar Ismail | G10: 10 Juli 2021 | H10: 2021 | J10: 1 | K10: 1 | M10: Laki-laki | N10: Yogyakarta | O10: 39705 | P10: 14 September 2008 | R10: 3402161409080004 | S10: Islam | T10: Jl. Wates No. 171 Rejodadi DK. XI Ngestiharjo Kasihan Bantul DI Yogyakarta 55181 | U10: 55181 | V10: Ngestiharjo | W10: Kasihan | X10: Bantul | Y10: DI Yogyakarta | Z10: MTs Mu'allimin Muh. Yogyakarta | AA10: Jl. Letjend. S. Parman No. 68 Yogyakarta | AC10: Mustafa Ismail | AD10: Islam | AE10: S1 | AF10: Karyawan Swasta | AH10: 081392565639 | AJ10: Prihatini Dwi Lestari | AK10: Islam | AL10: S1 | AM10: PNS | AO10: 081328797228 | AQ10: 3402160108090001 | AR10: 3402162103670003 | AS10: Bantul | AT10: 24552 | AV10: 3402164612730001 | AW10: Kulon Progo | AX10: 27004 | BA10: Islam | BH10: Ikhwanuddin, S.H.I., M.S.I. | BI10: 861149 | BJ10: H. Aly Aulia, Lc. M. Hum. | BK10: - / 865 966
A11: 10 | B11: C | C11: A | D11: 11002 | E11: 0086260742 | F11: Imaduddin Aufal Marom | G11: 10 Juli 2021 | H11: 2021 | J11: 3 | M11: Laki-laki | N11: Kulon Progo | O11: 39764 | P11: 12 November 2008 | S11: Islam | T11: Margosari Pengasih Kulon Progo DI Yogyakarta | U11: 55652 | V11: Margosari | W11: Pengasih | X11: Kulon Progo | Y11: DI Yogyakarta | Z11: MTs Mu'allimin Muh. Yogyakarta | AA11: Jl. Letjend. S. Parman No. 68 Yogyakarta | AC11: Djama'ah | AD11: Islam | AF11: PNS | AH11: 08122952085 | AJ11: Endang Puji Astuti | AK11: Islam | AM11: Lainnya | AO11: 081335330491 | BA11: Islam | BH11: Ikhwanuddin, S.H.I., M.S.I. | BI11: 861150 | BJ11: H. Aly Aulia, Lc. M. Hum. | BK11: - / 865 966
A12: 11 | B12: C | C12: A | D12: 11020 | E12: 0107989881 | F12: M. Kasyfi Rahman | G12: 10 Juli 2021 | H12: 2021 | J12: 3 | M12: Laki-laki | N12: Kota Medan | O12: 40221 | P12: 12 Februari 2010 | S12: Islam | T12: Jl. Jermal IV No 18 LK IV Denai Medan Denai Kota Medan Sumatera Utara | U12: 20227 | V12: Denai | W12: Medan Denai | X12: Kota Medan | Y12: Sumatera Utara | Z12: MTs Mu'allimin Muh. Yogyakarta | AA12: Jl. Letjend. S. Parman No. 68 Yogyakarta | AC12: Rafdinal S.Sos., MAP | AD12: Islam | AF12: Guru | AH12: 081260931435 | AJ12: Fitri Hidayati, S.Ag. | AK12: Islam | AM12: Lainnya | AO12: 081260931518 | BA12: Islam | BH12: Ikhwanuddin, S.H.I., M.S.I. | BI12: 861151 | BJ12: H. Aly Aulia, Lc. M. Hum. | BK12: - / 865 966
A13: 12 | B13: B | C13: A | D13: 11030 | E13: 0088996299 | F13: Miqdad | G13: 10 Juli 2021 | H13: 2021 | J13: 1 | K13: 2 | M13: Laki-laki | N13: Kulon Progo | O13: 39737 | P13: 16 Oktober 2008 | S13: Islam | T13: Sigran Dk.1 Tirtorahayu Galur Kulon Progo DI Yogyakarta 55661 | U13: 55661 | V13: Tirtorahayu | W13: Galur | X13: Kulon Progo | Y13: DI Yogyakarta | Z13: MTs Mu'allimin Muh. Yogyakarta | AA13: Jl. Letjend. S. Parman No. 68 Yogyakarta | AC13: Dwi Purwanto | AD13: Islam | AE13: SMP | AF13: Wiraswasta | AG13: di atas Rp. 5.000.000,- | AH13: 087739508999 | AI13: dpurwanto11@gmail.com | AJ13: Siti Maimunah | AK13: Islam | AL13: SMA | AM13: Lainnya | AN13: di bawah Rp. 2.000.000,- | AO13: 085292700115 | AS13: Kulon Progo | AT13: 30524 | AW13: Kulon Progo | AX13: 30101 | BA13: Islam | BH13: Ikhwanuddin, S.H.I., M.S.I. | BI13: 861152 | BJ13: H. Aly Aulia, Lc. M. Hum. | BK13: - / 865 966
A14: 13 | B14: C | C14: A | D14: 11031 | E14: 0094351972 | F14: Miqdad Nasrullah Ali | G14: 10 Juli 2021 | H14: 2021 | J14: 2 | M14: Laki-laki | N14: Yogyakarta | O14: 39847 | P14: 03 Februari 2009 | S14: Islam | T14: Jl. Nyi Pembayun 21 Prenggan Kotagede Kota Yogyakarta DI Yogyakarta | U14: 55172 | V14: Prenggan | W14: Kotagede | X14: Kota Yogyakarta | Y14: DI Yogyakarta | Z14: MTs Mu'allimin Muh. Yogyakarta | AA14: Jl. Letjend. S. Parman No. 68 Yogyakarta | AC14: AliYusuf, S.Th.I., M.Hum. | AD14: Islam | AF14: Dosen | AH14: 08562598433 | AJ14: Nishatin Ma'rifah, S.Pd.I. | AK14: Islam | AM14: PNS | AO14: 0895605910947 | BA14: Islam | BH14: Ikhwanuddin, S.H.I., M.S.I. | BI14: 861153 | BJ14: H. Aly Aulia, Lc. M. Hum. | BK14: - / 865 966
A15: 14 | B15: E | C15: A | D15: 11033 | E15: 0083979403 | F15: Moch. Gaidan Fahdani Ramadhan | G15: 10 Juli 2021 | H15: 2021 | J15: 2 | K15: 2 | M15: Laki-laki | N15: Bojonegoro | O15: 39720 | P15: 29 September 2008 | S15: Islam | T15: Ds. Sumengko RT 01/RW 01, Sumengku, Kec. Kalitidu, Kab. Bojonegoro, Jawa Timur 62152 | U15: 62152 | V15: Sumengku | W15: Kalitidu | X15: Bojonegoro | Y15: Jawa Timur | Z15: MTs Mu'allimin Muh. Yogyakarta | AA15: Jl. Letjend. S. Parman No. 68 Yogyakarta | AC15: Oko Hermawan | AD15: Islam | AE15: S1 | AF15: PNS | AH15: 081252129190 | AJ15: Nur Hafifah | AK15: Islam | AL15: SMA | AM15: Ibu Rumah Tangga | AO15: 082140944669 | AQ15: 3522161703080276 | AR15: 3522162810790003 | AS15: Bojonegoro | AT15: 29156 | AV15: 3522166507830003 | AW15: Banyuwangi | AX15: 30522 | BA15: Islam | BH15: Ikhwanuddin, S.H.I., M.S.I. | BI15: 861154 | BJ15: H. Aly Aulia, Lc. M. Hum. | BK15: - / 865 966
A16: 15 | B16: G | C16: A | D16: 11035 | E16: 0084580973 | F16: Mohammad Hamzah Raza Alfaridzi | G16: 10 Juli 2021 | H16: 2021 | J16: 1 | M16: Laki-laki | N16: Banyuwangi | O16: 39762 | P16: 10 November 2008 | S16: Islam | T16: Jl. Karimunjawa No. 28 Lateng Banyuwangi Jawa Timur | U16: 68413 | V16: Lateng | W16: Banyuwangi | X16: Banyuwangi | Y16: Jawa Timur | Z16: MTs Mu'allimin Muh. Yogyakarta | AA16: Jl. Letjend. S. Parman No. 68 Yogyakarta | AC16: Mohammad Mahyuddin Mirza | AD16: Islam | AF16: Wiraswasta | AH16: 081336153777 | AJ16: Dwi Mira Fiorita | AK16: Islam | AM16: Wiraswasta | AO16: 081336153777 | BA16: Islam | BH16: Ikhwanuddin, S.H.I., M.S.I. | BI16: 861155 | BJ16: H. Aly Aulia, Lc. M. Hum. | BK16: - / 865 966
A17: 16 | B17: C | C17: A | D17: 11038 | E17: 0092810141 | F17: Mozavy Rafsanjani | G17: 10 Juli 2021 | H17: 2021 | J17: 2 | M17: Laki-laki | N17: Labuan Bajo | O17: 40026 | P17: 01 Agustus 2009 | S17: Islam | T17: Jl. Soekarno Hatta, Kel. Labuan Bajo, Kec. Komodo, Kab. Manggarai Barat, NTT | U17: 86754 | V17: Labuan Bajo | W17: Komodo | X17: Manggarai Barat | Y17: Nusa Tenggara Timur | Z17: MTs Mu'allimin Muh. Yogyakarta | AA17: Jl. Letjend. S. Parman No. 68 Yogyakarta | AC17: Suwandhy | AD17: Islam | AF17: Wiraswasta | AH17: 081267111653 | AJ17: Marna Wati | AK17: Islam | AM17: Lainnya | AO17: 081238700881 | BA17: Islam | BH17: Ikhwanuddin, S.H.I., M.S.I. | BI17: 861156 | BJ17: H. Aly Aulia, Lc. M. Hum. | BK17: - / 865 966
A18: 17 | B18: D | C18: A | D18: 11065 | E18: 0098148727 | F18: Muhammad Fadhil Gadaffi | G18: 10 Juli 2021 | H18: 2021 | J18: 1 | K18: 1 | M18: Laki-laki | N18: Magelang | O18: 40128 | P18: 11 November 2009 | R18: 3371031111090001 | S18: Islam | T18: Jl. Raya Magelang-Semarang Km. 9,5 Sidosari Secang Magelang Jawa Tengah | U18: 56127 | V18: Sidosari | W18: Secang | X18: Magelang | Y18: Jawa Tengah | Z18: MTs Mu'allimin Muh. Yogyakarta | AA18: Jl. Letjend. S. Parman No. 68 Yogyakarta | AC18: Eri Budi Sudarmadi | AD18: Islam | AE18: Diploma | AF18: Wiraswasta | AH18: 085226406557 | AJ18: Lina Arum Sari | AK18: Islam | AL18: SMA | AM18: Ibu Rumah Tangga | AO18: 085226406557 | AQ18: 3371030701110001 | AR18: 3371011302790001 | AS18: Magelang | AT18: 28899 | AV18: 337102 | AW18: Magelang | BA18: Islam | BH18: Ikhwanuddin, S.H.I., M.S.I. | BI18: 861157 | BJ18: H. Aly Aulia, Lc. M. Hum. | BK18: - / 865 966
A19: 18 | B19: E | C19: A | D19: 11078 | E19: 0087662840 | F19: Muhammad Hafiizh Vernardyansyah | G19: 10 Juli 2021 | H19: 2021 | J19: 1 | K19: 1 | M19: Laki-laki | N19: Bantul | O19: 39724 | P19: 03 Oktober 2008 | R19: 3402160310080001 | S19: Islam | T19: Salam Bangunjiwo Kasihan Bantul DI Yogyakarta 55184 | U19: 55184 | V19: Bangunjiwo | W19: Kasihan | X19: Bantul | Y19: DI Yogyakarta | Z19: MTs Mu'allimin Muh. Yogyakarta | AA19: Jl. Letjend. S. Parman No. 68 Yogyakarta | AC19: Sunardiyono | AD19: Islam | AE19: Diploma | AF19: Guru | AH19: 087738384327 | AJ19: Dyah Harini, ST | AK19: Islam | AL19: S1 | AM19: PNS | AO19: 087738467267 | AQ19: 3402161306110016 | AR19: 3402161104800003 | AS19: Bantul | AT19: 29322 | AV19: 3402166706810005 | AW19: Bantul | AX19: 29764 | BA19: Islam | BH19: Ikhwanuddin, S.H.I., M.S.I. | BI19: 861158 | BJ19: H. Aly Aulia, Lc. M. Hum. | BK19: - / 865 966
A20: 19 | B20: J | C20: A | D20: 11087 | E20: 0084424612 | F20: Muhammad Luthfi Kurniawan | G20: 10 Juli 2021 | H20: 2021 | J20: 1 | M20: Laki-laki | N20: Yogyakarta | O20: 39686 | P20: 26 Agustus 2008 | S20: Islam | T20: Sutopadan, Ngestiharjo, Kasihan, Bantul DI Yogyakarta | U20: 55184 | V20: Ngestiharjo | W20: Kasihan | X20: Bantul | Y20: DI Yogyakarta | Z20: MTs Mu'allimin Muh. Yogyakarta | AA20: Jl. Letjend. S. Parman No. 68 Yogyakarta | AC20: Darundi | AD20: Islam | AF20: PNS | AH20: 089606944639 | AJ20: Asti Minarsih | AK20: Islam | AM20: Lainnya | AO20: 082224048610 | BA20: Islam | BH20: Ikhwanuddin, S.H.I., M.S.I. | BI20: 861159 | BJ20: H. Aly Aulia, Lc. M. Hum. | BK20: - / 865 966
A21: 20 | B21: F | C21: A | D21: 11093 | E21: 0087126742 | F21: Muhammad Nur Faiz | G21: 10 Juli 2021 | H21: 2021 | J21: 2 | M21: Laki-laki | N21: Yogyakarta | O21: 39734 | P21: 13 Oktober 2008 | S21: Islam | T21: Baciro GK 4/36 RT 41/RW 11 DI Yogyakarta 55225 | U21: 55225 | V21: Baciro | W21: Gondokusuman | X21: Kota Yogyakarta | Y21: DI Yogyakarta | Z21: MTs Mu'allimin Muh. Yogyakarta | AA21: Jl. Letjend. S. Parman No. 68 Yogyakarta | AC21: Nur Rendra Jatiarto | AD21: Islam | AF21: Lainnya | AH21: 081346506697 | AJ21: Eni Nur Sayekti | AK21: Islam | AM21: Wiraswasta | AO21: 08122751696 | BA21: Islam | BH21: Ikhwanuddin, S.H.I., M.S.I. | BI21: 861160 | BJ21: H. Aly Aulia, Lc. M. Hum. | BK21: - / 865 966
A22: 21 | B22: H | C22: A | D22: 11098 | E22: 0087026465 | F22: Muhammad Rafi' 'Athaullah | G22: 10 Juli 2021 | H22: 2021 | J22: 3 | M22: Laki-laki | N22: Sleman | O22: 39703 | P22: 12 September 2008 | S22: Islam | T22: Perumahan Jatisawit Asri Blok F6 RT 17 RW 43 Balecatur Gamping Sleman DIY 55295 | U22: 55295 | V22: Balecatur | W22: Gamping | X22: Sleman | Y22: DI Yogyakarta | Z22: MTs Mu'allimin Muh. Yogyakarta | AA22: Jl. Letjend. S. Parman No. 68 Yogyakarta | AC22: Wahyudiyono | AD22: Islam | AF22: Dosen | AH22: 08156805012 | AJ22: Eko Listyorini | AK22: Islam | AM22: Lainnya | AO22: 085105187939 | BA22: Islam | BH22: Ikhwanuddin, S.H.I., M.S.I. | BI22: 861161 | BJ22: H. Aly Aulia, Lc. M. Hum. | BK22: - / 865 966
A23: 22 | B23: G | C23: A | D23: 11121 | E23: 0086822076 | F23: Nabhan 'Abid Muhanna | G23: 10 Juli 2021 | H23: 2021 | J23: 2 | K23: 2 | M23: Laki-laki | N23: Blitar | O23: 39795 | P23: 13 Desember 2008 | R23: 35050911312080001 | S23: Islam | T23: Dsn. Jiwut RT 01/RW 10 Ds. Jiwut Kec. Nglegok, Kabupaten Blitar Jawa Timur 66181 | U23: 66181 | V23: Jiwut | W23: Nlegok | X23: Blitar | Y23: Jawa Timur | Z23: MTs Mu'allimin Muh. Yogyakarta | AA23: Jl. Letjend. S. Parman No. 68 Yogyakarta | AC23: Choirul Fata | AD23: Islam | AE23: Diploma | AF23: Peternak | AH23: 08123359159 | AJ23: Susilowati | AK23: Islam | AL23: SMA | AM23: Peternak | AO23: 081231567810 | AQ23: 3505091605064848 | AR23: 3505092611710001 | AS23: Blitar | AT23: 26263 | AV23: 3505095105780001 | AW23: Blitar | AX23: 28621 | BA23: Islam | BH23: Ikhwanuddin, S.H.I., M.S.I. | BI23: 861162 | BJ23: H. Aly Aulia, Lc. M. Hum. | BK23: - / 865 966
A24: 23 | B24: F | C24: A | D24: 11129 | E24: 0081466811 | F24: Nashiruddin Arwi Al-Musyafiq | G24: 10 Juli 2021 | H24: 2021 | J24: 2 | K24: 1 | M24: Laki-laki | N24: Ponorogo | O24: 39646 | P24: 17 Juli 2008 | R24: 35052031707080001 | S24: Islam | T24: Jalan Mijil Dukuh Klatakan Desa Belang Kecamatan Bungkal Kabupaten Ponorogo Jawa Timur 63462 | U24: 63462 | V24: Belang | W24: Bungkal | X24: Ponorogo | Y24: Jawa Timur | Z24: MTs Mu'allimin Muh. Yogyakarta | AA24: Jl. Letjend. S. Parman No. 68 Yogyakarta | AC24: Abdur Rohman | AD24: Islam | AE24: S1 | AF24: Guru | AH24: 081335693715 | AJ24: Wiwik Yuli Lestari | AK24: Islam | AL24: S1 | AM24: Guru | AO24: 081351937269 | AQ24: 3502032809010492 | AR24: 3502031407620003 | AS24: Ponorogo | AT24: 22841 | AV24: 3502036907670001 | AW24: 7/29/1967 | BA24: Islam | BH24: Ikhwanuddin, S.H.I., M.S.I. | BI24: 861163 | BJ24: H. Aly Aulia, Lc. M. Hum. | BK24: - / 865 966
A25: 24 | B25: H | C25: A | D25: 11150 | E25: 0084883117 | F25: Rafa Hamiz Azizan | G25: 10 Juli 2021 | H25: 2021 | J25: 1 | M25: Laki-laki | N25: Cilacap | O25: 39801 | P25: 19 Desember 2008 | S25: Islam | T25: Jl. Teropong Perum. Rindu Seerumpun 5 Blok F/3 Sidomulyo Barat Tampan Pekanbarau Riau | U25: 28294 | V25: Sidomulyo Barat | W25: Tampan | X25: Pekanbaru | Y25: Riau | Z25: MTs Mu'allimin Muh. Yogyakarta | AA25: Jl. Letjend. S. Parman No. 68 Yogyakarta | AC25: Zamri | AD25: Islam | AF25: Wiraswasta | AH25: 085278007461 | AJ25: Siska Maria Lestari | AK25: Islam | AM25: Lainnya | AO25: 085264925752 | BA25: Islam | BH25: Ikhwanuddin, S.H.I., M.S.I. | BI25: 861164 | BJ25: H. Aly Aulia, Lc. M. Hum. | BK25: - / 865 966
A26: 25 | B26: J | C26: A | D26: 11153 | E26: 0095371945 | F26: Rafif Attaya Zahran | G26: 10 Juli 2021 | H26: 2021 | J26: 1 | M26: Laki-laki | N26: Kulon Progo | O26: 39915 | P26: 12 April 2009 | S26: Islam | T26: Cabean Bumirejo Lendah Kulon Progo DIY | U26: 55663 | V26: Bumirejo | W26: Lendah | X26: Kulon Progo | Y26: DI Yogyakarta | Z26: MTs Mu'allimin Muh. Yogyakarta | AA26: Jl. Letjend. S. Parman No. 68 Yogyakarta | AC26: Bayu Rianto Nugroho, SE | AD26: Islam | AF26: Wiraswasta | AH26: 08121579118 | AJ26: Daning Kusniapuantari, S.T.P | AK26: Islam | AM26: Lainnya | AO26: 081328401857 | BA26: Islam | BH26: Ikhwanuddin, S.H.I., M.S.I. | BI26: 861165 | BJ26: H. Aly Aulia, Lc. M. Hum. | BK26: - / 865 966
A27: 26 | B27: C | C27: A | D27: 11156 | E27: 0096837925 | F27: Raihan Fadilah Anwar | G27: 10 Juli 2021 | H27: 2021 | J27: 1 | M27: Laki-laki | N27: Labuan Bajo | O27: 40021 | P27: 27 Juli 2009 | S27: Islam | T27: Kampung Air , Lingkungan IV Labuan Bajo Komodo Manggarai Barat NTT | U27: 86754 | V27: Labuan Bajo | W27: Komodo | X27: Manggarai | Y27: Nusa Tenggara Timur | Z27: MTs Mu'allimin Muh. Yogyakarta | AA27: Jl. Letjend. S. Parman No. 68 Yogyakarta | AC27: Anwar | AD27: Islam | AF27: TNI/Polri | AH27: 081238952822 | AJ27: Susanthi Effendhy | AK27: Islam | AM27: PNS | AO27: 081339459149 | BA27: Islam | BH27: Ikhwanuddin, S.H.I., M.S.I. | BI27: 861166 | BJ27: H. Aly Aulia, Lc. M. Hum. | BK27: - / 865 966
A28: 27 | B28: C | C28: A | D28: 11166 | E28: 0082244966 | F28: Ridwan Latief Abimanyu | G28: 10 Juli 2021 | H28: 2021 | J28: 2 | M28: Laki-laki | N28: Kulon Progo | O28: 39564 | P28: 26 April 2008 | S28: Islam | T28: Nusupan Trihanggo Gamping Sleman DIY | U28: 55291 | V28: Trihanggo | W28: Gamping | X28: Sleman | Y28: DI Yogyakarta | Z28: MTs Mu'allimin Muh. Yogyakarta | AA28: Jl. Letjend. S. Parman No. 68 Yogyakarta | AC28: Agus Sudarmanto | AD28: Islam | AF28: Wiraswasta | AH28: 082225983568 | AJ28: Sofia Lestari | AK28: Islam | AM28: PNS | AO28: 082225983568 | BA28: Islam | BH28: Ikhwanuddin, S.H.I., M.S.I. | BI28: 861167 | BJ28: H. Aly Aulia, Lc. M. Hum. | BK28: - / 865 966
A29: 28 | B29: B | C29: A | D29: 11174 | E29: 0088578558 | F29: Sholahudin Al-Ayyubi | G29: 10 Juli 2021 | H29: 2021 | J29: 2 | K29: 2 | M29: Laki-laki | N29: Surabaya | O29: 39703 | P29: 12 September 2008 | R29: 3578261209080004 | S29: Islam | T29: Jl. Mulyosari Tengah 7 No 18 Mulyorejo Surabaya Jawa Timur 60112 | U29: 60112 | V29: Mulyosari Tengah | W29: Mulyorejo | X29: Surabaya | Y29: Jawa Timur | Z29: MTs Mu'allimin Muh. Yogyakarta | AA29: Jl. Letjend. S. Parman No. 68 Yogyakarta | AC29: Rio Muhammad | AD29: Islam | AE29: S1 | AF29: Karyawan Swasta | AH29: 08215633354 | AJ29: Hikmah Ali | AK29: Islam | AL29: S1 | AM29: Ibu Rumah Tangga | AO29: 08113344314 | AQ29: 3578260402090001 | AR29: 3578262110840002 | AS29: Samarinda | AT29: 30976 | AV29: 3578264203840001 | AW29: Surabaya | AX29: 30743 | BA29: Islam | BH29: Ikhwanuddin, S.H.I., M.S.I. | BI29: 861168 | BJ29: H. Aly Aulia, Lc. M. Hum. | BK29: - / 865 966
A30: 29 | B30: I | C30: A | D30: 11180 | E30: 0076298289 | F30: Umar Al Faruq | G30: 10 Juli 2021 | H30: 2021 | J30: 2 | M30: Laki-laki | N30: Sragen | O30: 39445 | P30: 29 Desember 2007 | S30: Islam | T30: Margorejo, Jono, Rt/Rw 07/02, Tanon, Sragen, Jawa tengah | U30: 57277 | V30: Jono | W30: Tanon | X30: Sragen | Y30: Jawa tengah | Z30: MTs Mu'allimin Muh. Yogyakarta | AA30: Jl. Letjend. S. Parman No. 68 Yogyakarta | AC30: Joko Suratno | AD30: Islam | AF30: Wiraswasta | AH30: 081329696666 | AJ30: Endang Sri Rahayu | AK30: Islam | AM30: Wiraswasta | AO30: 082225621008 | BA30: Islam | BH30: Ikhwanuddin, S.H.I., M.S.I. | BI30: 861169 | BJ30: H. Aly Aulia, Lc. M. Hum. | BK30: - / 865 966
A31: 30 | B31: G | C31: A | D31: 11192 | E31: 0089521814 | F31: Zaydan Rafi Mubarak | G31: 10 Juli 2021 | H31: 2021 | J31: 1 | K31: 1 | M31: Laki-laki | N31: Yogyakarta | O31: 39735 | P31: 14 Oktober 2008 | R31: 3471131410080001 | S31: Islam | T31: Pakel Baru UH 6/1112 Sorosutan Umbulharjo Yogyakarta 55162 | U31: 55162 | V31: Sorosutan | W31: Umbulharjo | X31: Kota Yogyakarta | Y31: DI Yogyakarta | Z31: MTs Mu'allimin Muh. Yogyakarta | AA31: Jl. Letjend. S. Parman No. 68 Yogyakarta | AC31: Fikri Hajian Mubarak | AD31: Islam | AE31: SMA | AF31: Karyawan Swasta | AH31: 087738570755 | AJ31: Irawati | AK31: Islam | AL31: S1 | AM31: Karyawan Swasta | AO31: 081227565688 | AQ31: 3471132805070438 | AR31: 3471132508810004 | AS31: Yogyakarta | AT31: 29823 | AV31: 3471136312810002 | AW31: Klaten | AX31: 29943 | BA31: Islam | BH31: Ikhwanuddin, S.H.I., M.S.I. | BI31: 861170 | BJ31: H. Aly Aulia, Lc. M. Hum. | BK31: - / 865 966
A32: 31 | B32: A | C32: A | D32: 11193 | E32: 0098760415 | F32: Zolla Vajjero Amnestya | G32: 10 Juli 2021 | H32: 2021 | J32: 1 | K32: 2 | M32: Laki-laki | N32: Wonosobo | O32: 39849 | P32: 05 Februari 2009 | R32: 3307020502090002 | S32: Islam | T32: Gunung Saren Lor RT 083 Trimurti Srandakan Bantul DIY | U32: 55762 | V32: Trimurti | W32: Srandakan | X32: Bantul | Y32: DI Yogyakarta | Z32: MTs Mu'allimin Muh. Yogyakarta | AA32: Jl. Letjend. S. Parman No. 68 Yogyakarta | AC32: Purwanta | AD32: Islam | AE32: S1 | AF32: Guru | AG32: Rp. 2.000.000,- s/d Rp. 5.000.000,- | AH32: 087780653224 | AI32: Ddsyahrizal@gmail.com | AJ32: Siti Khotimah | AK32: Islam | AL32: S1 | AM32: Wiraswasta | AN32: di bawah Rp. 2.000.000,- | AO32: 085292827807 | AP32: zoraphalosa@gmail.com | AQ32: 3307030708120006 | AR32: 3402011010770001 | AS32: Bantul | AT32: 28408 | AV32: 3307024708800011 | AW32: Wonosobo | AX32: 29440 | AZ32: Purwanta | BA32: Islam | BB32: S1 | BC32: PNS | BD32: Gunungsaren lor Rt 83, Trimurti, srandakan, Bantul | BE32: Rp. 2.000.000,- s/d Rp. 5.000.000,- | BF32: 085647341724 | BH32: Ikhwanuddin, S.H.I., M.S.I. | BI32: 861171 | BJ32: H. Aly Aulia, Lc. M. Hum. | BK32: - / 865 966
A33: 1 | B33: B | C33: B | D33: 10888 | E33: 0087340961 | F33: Ahmad Faiz Ramadhiansyah | G33: 10 Juli 2021 | H33: 2021 | J33: 2 | K33: 2 | M33: Laki-laki | N33: Surabaya | O33: 39697 | P33: 06 September 2008 | S33: Islam | T33: Jl. Wisma Permai I No. 63 Mulyorejo Surabaya Jawa Timur 60115 | U33: 60115 | V33: Mulyorejo | W33: Mulyorejo | X33: Surabaya | Y33: Jawa Timur | Z33: MTs Mu'allimin Muh. Yogyakarta | AA33: Jl. Letjend. S. Parman No. 68 Yogyakarta | AC33: Asrul Irawan Bakhtiarsyah | AD33: Islam | AE33: S2 | AF33: Lainnya | AG33: di atas Rp. 5.000.000,- | AH33: 0818525176 | AI33: asrul.irawan@outlook.com | AJ33: Detti Nur Irawati, dr | AK33: Islam | AL33: S2 | AM33: Dokter | AN33: Rp. 2.000.000,- s/d Rp. 5.000.000,- | AO33: 08123059305 | AP33: detti.nur@gmail.com | AS33: Surabaya | AT33: 27532 | AW33: Surabaya | AX33: 27859 | BA33: Islam | BH33: Zulfi Jalal Muhsin, S.Pd. | BI33: 1120266 | BJ33: H. Aly Aulia, Lc. M. Hum. | BK33: - / 865 966
A34: 2 | B34: J | C34: B | D34: 10903 | E34: 0084723950 | F34: Alfario Futtaqi Hartono | G34: 10 Juli 2021 | H34: 2021 | J34: 1 | M34: Laki-laki | N34: Salatiga | O34: 39771 | P34: 19 November 2008 | S34: Islam | T34: Perumahan Taman Mutiara, Jl. Intan 1, Blok E1, No. 20-21 Tingkir Tengah Tingkir Salatiga Jawa Tengah | U34: 50745 | V34: Tingkir Tengah | W34: Tingkir | X34: Salatiga | Y34: Jawa Tengah | Z34: MTs Mu'allimin Muh. Yogyakarta | AA34: Jl. Letjend. S. Parman No. 68 Yogyakarta | AC34: Effendi Hartono | AD34: Islam | AF34: Lainnya | AH34: 08123479101 | AJ34: Siti Asmaul Hasanah | AK34: Islam | AM34: Lainnya | AO34: 081330457473 | BA34: Islam | BH34: Zulfi Jalal Muhsin, S.Pd. | BI34: 1120266 | BJ34: H. Aly Aulia, Lc. M. Hum. | BK34: - / 865 966
A35: 3 | B35: A | C35: B | D35: 10904 | E35: 0086954015 | F35: Alfi Khairi Mumtaza | G35: 10 Juli 2021 | H35: 2021 | M35: Laki-laki | N35: Muara Badak | O35: 39715 | P35: 24 September 2008 | S35: Islam | T35: Gang Rapak Indah Jembayan Loa Kulu Kutai Kartanegara Kalimantan Timur | U35: 75571 | V35: Jembayan | W35: Loa Kulu | X35: Kutai Kartanegara | Y35: Kalimantan Timur | Z35: MTs Mu'allimin Muh. Yogyakarta | AA35: Jl. Letjend. S. Parman No. 68 Yogyakarta | AB35: Prestasi Akademik : Peringkat 1 dari kelas I sampai kelas V | AC35: Drs. H. Ihsanul Karim, MM, MH | AD35: Islam | AE35: S2 | AF35: PNS | AG35: Rp. 2.000.000,- s/d Rp. 5.000.000,- | AH35: 081254322269 | AI35: alkarimihsan@gmail.com | AJ35: Hj. Dariana Juhaida, S.Ag | AK35: Islam | AL35: S1 | AM35: PNS | AN35: Rp. 2.000.000,- s/d Rp. 5.000.000,- | AO35: 08125884922 | AP35: dariana24091972@gmail.com | BH35: Zulfi Jalal Muhsin, S.Pd. | BI35: 1120267 | BJ35: H. Aly Aulia, Lc. M. Hum. | BK35: - / 865 966
A36: 4 | B36: G | C36: B | D36: 10912 | E36: 0092792362 | F36: Arkan Zumair Hisyam | G36: 10 Juli 2021 | H36: 2021 | J36: 1 | K36: 1 | M36: Laki-laki | N36: Klaten | O36: 39873 | P36: 01 Maret 2009 | R36: 3310240103090001 | S36: Islam | T36: Margomulyo Gergunung Klaten Utara Klaten Jawa Tengah 57434 | U36: 57434 | V36: Gergunung | W36: Klaten Utara | X36: Klaten | Y36: Jawa Tengah | Z36: MTs Mu'allimin Muh. Yogyakarta | AA36: Jl. Letjend. S. Parman No. 68 Yogyakarta | AC36: Hermawan Yuliyanto | AD36: Islam | AE36: SMA | AF36: TNI/Polri | AH36: 085293757171 | AJ36: Ani Ernawati | AK36: Islam | AL36: Diploma | AM36: PNS | AO36: 085229447555 | AQ36: 3310242405120006 | AR36: 3310021707720002 | AS36: Klaten | AT36: 26497 | AV36: 3310025706810002 | AW36: Klaten | AX36: 29754 | BA36: Islam | BH36: Zulfi Jalal Muhsin, S.Pd. | BI36: 1120268 | BJ36: H. Aly Aulia, Lc. M. Hum. | BK36: - / 865 966
A37: 5 | B37: H | C37: B | D37: 10917 | E37: 0092059445 | F37: Aryasatya Kayana Hasyim | G37: 10 Juli 2021 | H37: 2021 | J37: 1 | M37: Laki-laki | N37: Yogyakarta | O37: 39824 | P37: 11 Januari 2009 | S37: Islam | T37: Jln. Magelang Km 11 Dukuh RT 02 RW 17 Tridadi Sleman DI Yogyakarta | U37: 55511 | V37: Tridadi | W37: Sleman | X37: Sleman | Y37: DI Yogyakarta | Z37: MTs Mu'allimin Muh. Yogyakarta | AA37: Jl. Letjend. S. Parman No. 68 Yogyakarta | AC37: Wahid Nurhasyim | AD37: Islam | AF37: Lainnya | AH37: 082227049650 | AJ37: Anesti Purwandari | AK37: Islam | AM37: Lainnya | AO37: 081226704220 | BA37: Islam | BH37: Zulfi Jalal Muhsin, S.Pd. | BI37: 1120269 | BJ37: H. Aly Aulia, Lc. M. Hum. | BK37: - / 865 966
A38: 6 | B38: I | C38: B | D38: 10928 | E38: 0094806637 | F38: Azmi Akrami Maha | G38: 10 Juli 2021 | H38: 2021 | J38: 3 | K38: 2 | M38: Laki-laki | N38: Yogyakarta | O38: 39928 | P38: 25 April 2009 | R38: 3404012504090004 | S38: Islam | T38: Perumahan Jatisawit Asri Blok F6 RT 17 RW 43 Balecatur Gamping Sleman DIY 55295 | U38: 55295 | V38: Balecatur | W38: Gamping | X38: Sleman | Y38: DI Yogyakarta | Z38: MTs Mu'allimin Muh. Yogyakarta | AA38: Jl. Letjend. S. Parman No. 68 Yogyakarta | AC38: H. Guntar Maha, ST., MT. | AD38: Islam | AE38: S1 | AF38: PNS | AH38: 082242288889 | AJ38: Uu Faridah | AK38: Islam | AL38: Diploma | AM38: Wiraswasta | AO38: 082122021234 | AQ38: 3404012601050129 | AR38: 3404012201630001 | AS38: Dairi, Sidikalang | AT38: 23033 | AV38: 3404015703680002 | AW38: Cilacap | AX38: 24914 | BA38: Islam | BH38: Zulfi Jalal Muhsin, S.Pd. | BI38: 1120270 | BJ38: H. Aly Aulia, Lc. M. Hum. | BK38: - / 865 966
A39: 7 | B39: I | C39: B | D39: 10931 | E39: 0098080142 | F39: Bahtiar Aulia | G39: 10 Juli 2021 | H39: 2021 | J39: 1 | M39: Laki-laki | N39: Pemalang | O39: 39898 | P39: 26 Maret 2009 | S39: Islam | T39: Dusun Balutan RT 10 RW 04 Kelurahan Purwoharjo Kecamatan Comal Kabupaten Pemalang (Jl. A. Yani no. 05 Comal) Jawa Tengah | U39: 52363 | V39: Purwoharjo | W39: Comal | X39: Pemalang | Y39: Jawa Tengah | Z39: MTs Mu'allimin Muh. Yogyakarta | AA39: Jl. Letjend. S. Parman No. 68 Yogyakarta | AC39: Yulhan Efendi | AD39: Islam | AF39: Wiraswasta | AH39: 081328772087 | AJ39: Nur Khasanah BS | AK39: Islam | AM39: Wiraswasta | AO39: 087764911116 | BA39: Islam | BH39: Zulfi Jalal Muhsin, S.Pd. | BI39: 1120271 | BJ39: H. Aly Aulia, Lc. M. Hum. | BK39: - / 865 966
A40: 8 | B40: J | C40: B | D40: 10933 | E40: 0082125557 | F40: Bilal Salmana Firdaus | G40: 10 Juli 2021 | H40: 2021 | J40: 2 | M40: Laki-laki | N40: Salatiga | O40: 39774 | P40: 22 November 2008 | S40: Islam | T40: Wiroyudan Tingkir Tengah Tingkir Salatiga Jawa Tengah | U40: 50745 | V40: Tingkir Tengah | W40: Tingkir | X40: Salatiga | Y40: Jawa Tengah | Z40: MTs Mu'allimin Muh. Yogyakarta | AA40: Jl. Letjend. S. Parman No. 68 Yogyakarta | AC40: Randy Irawan | AD40: Islam | AF40: Wiraswasta | AH40: 082221106106 | AJ40: Kristiani Kurnia Dewi | AK40: Islam | AM40: Lainnya | AO40: 085727375766 | BA40: Islam | BH40: Zulfi Jalal Muhsin, S.Pd. | BI40: 1120272 | BJ40: H. Aly Aulia, Lc. M. Hum. | BK40: - / 865 966
...

Sheet PERKELAS
A1: PARALEL | B1: NO | C1: INDUK | D1: NISN | E1: NAMA SISWA | F1: Jenis Kelamin | G1: TEMPAT LAHIR | H1: TANGGAL LAHIR | I1: Agama | J1: Anak Ke | K1: Jml Saudara | L1: Alamat Tempat Tinggal | M1: KELURAHAN | N1: KECAMATAN | O1: Kabupaten/kota | P1: Provinsi | Q1: Asal Sekolah | R1: Alamat Sekolah | S1: Prestasi | T1: Nama Ayah | U1: Agama Ayah | V1: Pendidikan | W1: Pekerjaan | X1: Penghasilan | Y1: Telp | Z1: Email | AA1: Nama Ibu | AB1: Agama Ibu | AC1: Pendidikan | AD1: Pekerjaan | AE1: Penghasilan | AF1: Telp | AG1: Email | AH1: Nama Wali | AI1: Agama Wali | AJ1: Pendidikan | AK1: Pekerjaan | AL1: Alamat Wali | AM1: Penghasilan | AN1: Telp | AO1: Email | AP1: Nama WK
A2: A | B2: 4 | C2: ='BIO DATA'!D2 -> 10886 | D2: ='BIO DATA'!E2 -> 0082005792 | E2: ='BIO DATA'!F2:F32 -> Ahmad Abrisam Awaluddin Fadlur Rahman | F2: ='BIO DATA'!M2 -> Laki-laki | G2: ='BIO DATA'!N2 -> Surabaya | H2: ='BIO DATA'!O2 -> 39612 | I2: ='BIO DATA'!S2 -> Islam | J2: ='BIO DATA'!J2 -> 1 | K2: ='BIO DATA'!K2 -> 0 | L2: ='BIO DATA'!T2 -> Jl. Jemurwonosari Gang I No 16 B Wonocolo Surabaya Jawa Timur | M2: ='BIO DATA'!V2 -> Jemursari | N2: ='BIO DATA'!W2 -> Wonocolo | O2: ='BIO DATA'!X2 -> Surabaya | P2: ='BIO DATA'!Y2 -> Jawa Timur | Q2: ='BIO DATA'!Z2 -> MTs Mu'allimin Muh. Yogyakarta | R2: ='BIO DATA'!AA2 -> Jl. Letjend. S. Parman No. 68 Yogyakarta | S2: ='BIO DATA'!AB2 -> 0 | T2: ='BIO DATA'!AC2 -> Mukhlasin, ST., M.Pd. | ... AG2: ='BIO DATA'!AP2 -> 0 | AH2: ='BIO DATA'!AZ2 -> 0 | AI2: ='BIO DATA'!BA2 -> Islam | AJ2: ='BIO DATA'!BB2 -> 0 | AK2: ='BIO DATA'!BC2 -> 0 | AL2: ='BIO DATA'!BD2 -> 0 | AM2: ='BIO DATA'!BE2 -> 0 | AN2: ='BIO DATA'!BF2 -> 0 | AO2: ='BIO DATA'!BG2 -> 0 | AP2: ='BIO DATA'!BH2 -> Ikhwanuddin, S.H.I., M.S.I.
A3: A | B3: 13 | C3: ='BIO DATA'!D3 -> 10907 | D3: ='BIO DATA'!E3 -> 0081641644 | E3: ='BIO DATA'!F3:F33 -> Arash Fardad Muhammad Fateh | F3: ='BIO DATA'!M3 -> Laki-laki | G3: ='BIO DATA'!N3 -> Magelang | H3: ='BIO DATA'!O3 -> 39630 | I3: ='BIO DATA'!S3 -> Islam | J3: ='BIO DATA'!J3 -> 1 | K3: ='BIO DATA'!K3 -> 2 | L3: ='BIO DATA'!T3 -> Mingking Sokorini Muntilan Kab. Magelang Jawa Tengah 56451 | M3: ='BIO DATA'!V3 -> Sokorini | N3: ='BIO DATA'!W3 -> Muntilan | O3: ='BIO DATA'!X3 -> Magelang | P3: ='BIO DATA'!Y3 -> Jawa Tengah | Q3: ='BIO DATA'!Z3 -> MTs Mu'allimin Muh. Yogyakarta | R3: ='BIO DATA'!AA3 -> Jl. Letjend. S. Parman No. 68 Yogyakarta | S3: ='BIO DATA'!AB3 -> 0 | T3: ='BIO DATA'!AC3 -> Ahmad Abdul Jabar | ... AG3: ='BIO DATA'!AP3 -> 0 | AH3: ='BIO DATA'!AZ3 -> 0 | AI3: ='BIO DATA'!BA3 -> Islam | AJ3: ='BIO DATA'!BB3 -> 0 | AK3: ='BIO DATA'!BC3 -> 0 | AL3: ='BIO DATA'!BD3 -> 0 | AM3: ='BIO DATA'!BE3 -> 0 | AN3: ='BIO DATA'!BF3 -> 0 | AO3: ='BIO DATA'!BG3 -> 0 | AP3: ='BIO DATA'!BH3 -> Ikhwanuddin, S.H.I., M.S.I.
A4: A | B4: 25 | C4: ='BIO DATA'!D4 -> 10908 | D4: ='BIO DATA'!E4 -> 0089552731 | E4: ='BIO DATA'!F4:F34 -> Ardiansyah Rafi Ramadhan | F4: ='BIO DATA'!M4 -> Laki-laki | G4: ='BIO DATA'!N4 -> Yogyakarta | H4: ='BIO DATA'!O4 -> 39693 | I4: ='BIO DATA'!S4 -> Islam | J4: ='BIO DATA'!J4 -> 1 | K4: ='BIO DATA'!K4 -> 0 | L4: ='BIO DATA'!T4 -> Warungboto, Umbulharjo 4 RT 31 RW 08 No 868 Kota Yogyakarta DI Yogyakarta | M4: ='BIO DATA'!V4 -> Warungboto | N4: ='BIO DATA'!W4 -> Umbulharjo | O4: ='BIO DATA'!X4 -> Kota Yogyakarta | P4: ='BIO DATA'!Y4 -> DI Yogyakarta | Q4: ='BIO DATA'!Z4 -> MTs Mu'allimin Muh. Yogyakarta | R4: ='BIO DATA'!AA4 -> Jl. Letjend. S. Parman No. 68 Yogyakarta | S4: ='BIO DATA'!AB4 -> 0 | T4: ='BIO DATA'!AC4 -> Muhammad Ma'ruf | ... AG4: ='BIO DATA'!AP4 -> 0 | AH4: ='BIO DATA'!AZ4 -> 0 | AI4: ='BIO DATA'!BA4 -> Islam | AJ4: ='BIO DATA'!BB4 -> 0 | AK4: ='BIO DATA'!BC4 -> 0 | AL4: ='BIO DATA'!BD4 -> 0 | AM4: ='BIO DATA'!BE4 -> 0 | AN4: ='BIO DATA'!BF4 -> 0 | AO4: ='BIO DATA'!BG4 -> 0 | AP4: ='BIO DATA'!BH4 -> Ikhwanuddin, S.H.I., M.S.I.
A5: A | B5: 27 | C5: ='BIO DATA'!D5 -> 10930 | D5: ='BIO DATA'!E5 -> 3081859596 | E5: ='BIO DATA'!F5:F35 -> Bagus Murtadha Ayyasy Putra Amin | F5: ='BIO DATA'!M5 -> Laki-laki | G5: ='BIO DATA'!N5 -> Wonosobo | H5: ='BIO DATA'!O5 -> 39690 | I5: ='BIO DATA'!S5 -> Islam | J5: ='BIO DATA'!J5 -> 4 | K5: ='BIO DATA'!K5 -> 0 | L5: ='BIO DATA'!T5 -> Tuksari Kejajar Wonosobo Jawa Tengah | M5: ='BIO DATA'!V5 -> Tuksari | N5: ='BIO DATA'!W5 -> Kejajar | O5: ='BIO DATA'!X5 -> Wonosobo | P5: ='BIO DATA'!Y5 -> Jawa Tengah | Q5: ='BIO DATA'!Z5 -> MTs Mu'allimin Muh. Yogyakarta | R5: ='BIO DATA'!AA5 -> Jl. Letjend. S. Parman No. 68 Yogyakarta | S5: ='BIO DATA'!AB5 -> 0 | T5: ='BIO DATA'!AC5 -> Aminudin | ... AG5: ='BIO DATA'!AP5 -> 0 | AH5: ='BIO DATA'!AZ5 -> 0 | AI5: ='BIO DATA'!BA5 -> Islam | AJ5: ='BIO DATA'!BB5 -> 0 | AK5: ='BIO DATA'!BC5 -> 0 | AL5: ='BIO DATA'!BD5 -> 0 | AM5: ='BIO DATA'!BE5 -> 0 | AN5: ='BIO DATA'!BF5 -> 0 | AO5: ='BIO DATA'!BG5 -> 0 | AP5: ='BIO DATA'!BH5 -> Ikhwanuddin, S.H.I., M.S.I.
A6: A | B6: 35 | C6: ='BIO DATA'!D6 -> 10973 | D6: ='BIO DATA'!E6 -> 0094471717 | E6: ='BIO DATA'!F6:F36 -> Fathurrahman Al-Mumtaz | F6: ='BIO DATA'!M6 -> Laki-laki | G6: ='BIO DATA'!N6 -> Semarang | H6: ='BIO DATA'!O6 -> 39986 | I6: ='BIO DATA'!S6 -> Islam | J6: ='BIO DATA'!J6 -> 2 | K6: ='BIO DATA'!K6 -> 1 | L6: ='BIO DATA'!T6 -> Pedukuhan Senuko Sidoagung Godean Sleman DI Yogyakarta | M6: ='BIO DATA'!V6 -> Sidoagung | N6: ='BIO DATA'!W6 -> Godean | O6: ='BIO DATA'!X6 -> Sleman | P6: ='BIO DATA'!Y6 -> DI Yogyakarta | Q6: ='BIO DATA'!Z6 -> MTs Mu'allimin Muh. Yogyakarta | R6: ='BIO DATA'!AA6 -> Jl. Letjend. S. Parman No. 68 Yogyakarta | S6: ='BIO DATA'!AB6 -> 0 | T6: ='BIO DATA'!AC6 -> H. Eva Kumala Pontas, ST | ... AG6: ='BIO DATA'!AP6 -> hastuti.ramadhana20@gmail.com | AH6: ='BIO DATA'!AZ6 -> 0 | AI6: ='BIO DATA'!BA6 -> Islam | AJ6: ='BIO DATA'!BB6 -> 0 | AK6: ='BIO DATA'!BC6 -> 0 | AL6: ='BIO DATA'!BD6 -> 0 | AM6: ='BIO DATA'!BE6 -> 0 | AN6: ='BIO DATA'!BF6 -> 0 | AO6: ='BIO DATA'!BG6 -> 0 | AP6: ='BIO DATA'!BH6 -> Ikhwanuddin, S.H.I., M.S.I.
A7: A | B7: 44 | C7: ='BIO DATA'!D7 -> 10975 | D7: ='BIO DATA'!E7 -> 0091610526 | E7: ='BIO DATA'!F7:F37 -> Fatih Fazliansyah | F7: ='BIO DATA'!M7 -> Laki-laki | G7: ='BIO DATA'!N7 -> Tangerang | H7: ='BIO DATA'!O7 -> 39913 | I7: ='BIO DATA'!S7 -> Islam | J7: ='BIO DATA'!J7 -> 1 | K7: ='BIO DATA'!K7 -> 0 | L7: ='BIO DATA'!T7 -> Jl. Masjid Baiturrahman Porisgaga Baru Batu Ceper Tangerang Banten | M7: ='BIO DATA'!V7 -> Porisgaga Baru | N7: ='BIO DATA'!W7 -> Batu Ceper | O7: ='BIO DATA'!X7 -> Tangerang | P7: ='BIO DATA'!Y7 -> Banten | Q7: ='BIO DATA'!Z7 -> MTs Mu'allimin Muh. Yogyakarta | R7: ='BIO DATA'!AA7 -> Jl. Letjend. S. Parman No. 68 Yogyakarta | S7: ='BIO DATA'!AB7 -> 0 | T7: ='BIO DATA'!AC7 -> Firmansyah | ... AG7: ='BIO DATA'!AP7 -> 0 | AH7: ='BIO DATA'!AZ7 -> 0 | AI7: ='BIO DATA'!BA7 -> Islam | AJ7: ='BIO DATA'!BB7 -> 0 | AK7: ='BIO DATA'!BC7 -> 0 | AL7: ='BIO DATA'!BD7 -> 0 | AM7: ='BIO DATA'!BE7 -> 0 | AN7: ='BIO DATA'!BF7 -> 0 | AO7: ='BIO DATA'!BG7 -> 0 | AP7: ='BIO DATA'!BH7 -> Ikhwanuddin, S.H.I., M.S.I.
A8: A | B8: 56 | C8: ='BIO DATA'!D8 -> 10986 | D8: ='BIO DATA'!E8 -> 0081988453 | E8: ='BIO DATA'!F8:F38 -> Ghatfan Muhammad Attar | F8: ='BIO DATA'!M8 -> Laki-laki | G8: ='BIO DATA'!N8 -> Bekasi | H8: ='BIO DATA'!O8 -> 39719 | I8: ='BIO DATA'!S8 -> Islam | J8: ='BIO DATA'!J8 -> 3 | K8: ='BIO DATA'!K8 -> 2 | L8: ='BIO DATA'!T8 -> Jl. Gambir Sawit No. 18B 042/011 Pandeyan Umbulharjo Kota Yogyakarta DIY 55161 | M8: ='BIO DATA'!V8 -> Pandeyan | N8: ='BIO DATA'!W8 -> Umbulharjo | O8: ='BIO DATA'!X8 -> Kota Yogyakarta | P8: ='BIO DATA'!Y8 -> DI Yogyakarta | Q8: ='BIO DATA'!Z8 -> MTs Mu'allimin Muh. Yogyakarta | R8: ='BIO DATA'!AA8 -> Jl. Letjend. S. Parman No. 68 Yogyakarta | S8: ='BIO DATA'!AB8 -> 0 | T8: ='BIO DATA'!AC8 -> Bambang Margarita, A.Md. | ... AG8: ='BIO DATA'!AP8 -> 0 | AH8: ='BIO DATA'!AZ8 -> 0 | AI8: ='BIO DATA'!BA8 -> Islam | AJ8: ='BIO DATA'!BB8 -> 0 | AK8: ='BIO DATA'!BC8 -> 0 | AL8: ='BIO DATA'!BD8 -> 0 | AM8: ='BIO DATA'!BE8 -> 0 | AN8: ='BIO DATA'!BF8 -> 0 | AO8: ='BIO DATA'!BG8 -> 0 | AP8: ='BIO DATA'!BH8 -> Ikhwanuddin, S.H.I., M.S.I.
A9: A | B9: 76 | C9: ='BIO DATA'!D9 -> 10989 | D9: ='BIO DATA'!E9 -> 0092583854 | E9: ='BIO DATA'!F9:F39 -> Ghozi Yazid Rahman | F9: ='BIO DATA'!M9 -> Laki-laki | G9: ='BIO DATA'!N9 -> Purworejo | H9: ='BIO DATA'!O9 -> 39821 | I9: ='BIO DATA'!S9 -> Islam | J9: ='BIO DATA'!J9 -> 2 | K9: ='BIO DATA'!K9 -> 0 | L9: ='BIO DATA'!T9 -> Jl. Gatot Subroto No. 461 Keseneng Purworejo Jawa Tengah | M9: ='BIO DATA'!V9 -> Keseneng | N9: ='BIO DATA'!W9 -> Purworejo | O9: ='BIO DATA'!X9 -> Purworejo | P9: ='BIO DATA'!Y9 -> Jawa Tengah | Q9: ='BIO DATA'!Z9 -> MTs Mu'allimin Muh. Yogyakarta | R9: ='BIO DATA'!AA9 -> Jl. Letjend. S. Parman No. 68 Yogyakarta | S9: ='BIO DATA'!AB9 -> 0 | T9: ='BIO DATA'!AC9 -> Bakhruni Rakhman | ... AG9: ='BIO DATA'!AP9 -> 0 | AH9: ='BIO DATA'!AZ9 -> 0 | AI9: ='BIO DATA'!BA9 -> Islam | AJ9: ='BIO DATA'!BB9 -> 0 | AK9: ='BIO DATA'!BC9 -> 0 | AL9: ='BIO DATA'!BD9 -> 0 | AM9: ='BIO DATA'!BE9 -> 0 | AN9: ='BIO DATA'!BF9 -> 0 | AO9: ='BIO DATA'!BG9 -> 0 | AP9: ='BIO DATA'!BH9 -> Ikhwanuddin, S.H.I., M.S.I.
A10: A | B10: 83 | C10: ='BIO DATA'!D10 -> 10997 | D10: ='BIO DATA'!E10 -> 0094445811 | E10: ='BIO DATA'!F10:F40 -> Hibban Ammar Ismail | F10: ='BIO DATA'!M10 -> Laki-laki | G10: ='BIO DATA'!N10 -> Yogyakarta | H10: ='BIO DATA'!O10 -> 39705 | I10: ='BIO DATA'!S10 -> Islam | J10: ='BIO DATA'!J10 -> 1 | K10: ='BIO DATA'!K10 -> 1 | L10: ='BIO DATA'!T10 -> Jl. Wates No. 171 Rejodadi DK. XI Ngestiharjo Kasihan Bantul DI Yogyakarta 55181 | M10: ='BIO DATA'!V10 -> Ngestiharjo | N10: ='BIO DATA'!W10 -> Kasihan | O10: ='BIO DATA'!X10 -> Bantul | P10: ='BIO DATA'!Y10 -> DI Yogyakarta | Q10: ='BIO DATA'!Z10 -> MTs Mu'allimin Muh. Yogyakarta | R10: ='BIO DATA'!AA10 -> Jl. Letjend. S. Parman No. 68 Yogyakarta | S10: ='BIO DATA'!AB10 -> 0 | T10: ='BIO DATA'!AC10 -> Mustafa Ismail | ... AG10: ='BIO DATA'!AP10 -> 0 | AH10: ='BIO DATA'!AZ10 -> 0 | AI10: ='BIO DATA'!BA10 -> Islam | AJ10: ='BIO DATA'!BB10 -> 0 | AK10: ='BIO DATA'!BC10 -> 0 | AL10: ='BIO DATA'!BD10 -> 0 | AM10: ='BIO DATA'!BE10 -> 0 | AN10: ='BIO DATA'!BF10 -> 0 | AO10: ='BIO DATA'!BG10 -> 0 | AP10: ='BIO DATA'!BH10 -> Ikhwanuddin, S.H.I., M.S.I.
A11: A | B11: 85 | C11: ='BIO DATA'!D11 -> 11002 | D11: ='BIO DATA'!E11 -> 0086260742 | E11: ='BIO DATA'!F11:F41 -> Imaduddin Aufal Marom | F11: ='BIO DATA'!M11 -> Laki-laki | G11: ='BIO DATA'!N11 -> Kulon Progo | H11: ='BIO DATA'!O11 -> 39764 | I11: ='BIO DATA'!S11 -> Islam | J11: ='BIO DATA'!J11 -> 3 | K11: ='BIO DATA'!K11 -> 0 | L11: ='BIO DATA'!T11 -> Margosari Pengasih Kulon Progo DI Yogyakarta | M11: ='BIO DATA'!V11 -> Margosari | N11: ='BIO DATA'!W11 -> Pengasih | O11: ='BIO DATA'!X11 -> Kulon Progo | P11: ='BIO DATA'!Y11 -> DI Yogyakarta | Q11: ='BIO DATA'!Z11 -> MTs Mu'allimin Muh. Yogyakarta | R11: ='BIO DATA'!AA11 -> Jl. Letjend. S. Parman No. 68 Yogyakarta | S11: ='BIO DATA'!AB11 -> 0 | T11: ='BIO DATA'!AC11 -> Djama'ah | ... AG11: ='BIO DATA'!AP11 -> 0 | AH11: ='BIO DATA'!AZ11 -> 0 | AI11: ='BIO DATA'!BA11 -> Islam | AJ11: ='BIO DATA'!BB11 -> 0 | AK11: ='BIO DATA'!BC11 -> 0 | AL11: ='BIO DATA'!BD11 -> 0 | AM11: ='BIO DATA'!BE11 -> 0 | AN11: ='BIO DATA'!BF11 -> 0 | AO11: ='BIO DATA'!BG11 -> 0 | AP11: ='BIO DATA'!BH11 -> Ikhwanuddin, S.H.I., M.S.I.
A12: A | B12: 95 | C12: ='BIO DATA'!D12 -> 11020 | D12: ='BIO DATA'!E12 -> 0107989881 | E12: ='BIO DATA'!F12:F42 -> M. Kasyfi Rahman | F12: ='BIO DATA'!M12 -> Laki-laki | G12: ='BIO DATA'!N12 -> Kota Medan | H12: ='BIO DATA'!O12 -> 40221 | I12: ='BIO DATA'!S12 -> Islam | J12: ='BIO DATA'!J12 -> 3 | K12: ='BIO DATA'!K12 -> 0 | L12: ='BIO DATA'!T12 -> Jl. Jermal IV No 18 LK IV Denai Medan Denai Kota Medan Sumatera Utara | M12: ='BIO DATA'!V12 -> Denai | N12: ='BIO DATA'!W12 -> Medan Denai | O12: ='BIO DATA'!X12 -> Kota Medan | P12: ='BIO DATA'!Y12 -> Sumatera Utara | Q12: ='BIO DATA'!Z12 -> MTs Mu'allimin Muh. Yogyakarta | R12: ='BIO DATA'!AA12 -> Jl. Letjend. S. Parman No. 68 Yogyakarta | S12: ='BIO DATA'!AB12 -> 0 | T12: ='BIO DATA'!AC12 -> Rafdinal S.Sos., MAP | ... AG12: ='BIO DATA'!AP12 -> 0 | AH12: ='BIO DATA'!AZ12 -> 0 | AI12: ='BIO DATA'!BA12 -> Islam | AJ12: ='BIO DATA'!BB12 -> 0 | AK12: ='BIO DATA'!BC12 -> 0 | AL12: ='BIO DATA'!BD12 -> 0 | AM12: ='BIO DATA'!BE12 -> 0 | AN12: ='BIO DATA'!BF12 -> 0 | AO12: ='BIO DATA'!BG12 -> 0 | AP12: ='BIO DATA'!BH12 -> Ikhwanuddin, S.H.I., M.S.I.
A13: A | B13: 105 | C13: ='BIO DATA'!D13 -> 11030 | D13: ='BIO DATA'!E13 -> 0088996299 | E13: ='BIO DATA'!F13:F43 -> Miqdad | F13: ='BIO DATA'!M13 -> Laki-laki | G13: ='BIO DATA'!N13 -> Kulon Progo | H13: ='BIO DATA'!O13 -> 39737 | I13: ='BIO DATA'!S13 -> Islam | J13: ='BIO DATA'!J13 -> 1 | K13: ='BIO DATA'!K13 -> 2 | L13: ='BIO DATA'!T13 -> Sigran Dk.1 Tirtorahayu Galur Kulon Progo DI Yogyakarta 55661 | M13: ='BIO DATA'!V13 -> Tirtorahayu | N13: ='BIO DATA'!W13 -> Galur | O13: ='BIO DATA'!X13 -> Kulon Progo | P13: ='BIO DATA'!Y13 -> DI Yogyakarta | Q13: ='BIO DATA'!Z13 -> MTs Mu'allimin Muh. Yogyakarta | R13: ='BIO DATA'!AA13 -> Jl. Letjend. S. Parman No. 68 Yogyakarta | S13: ='BIO DATA'!AB13 -> 0 | T13: ='BIO DATA'!AC13 -> Dwi Purwanto | ... AG13: ='BIO DATA'!AP13 -> 0 | AH13: ='BIO DATA'!AZ13 -> 0 | AI13: ='BIO DATA'!BA13 -> Islam | AJ13: ='BIO DATA'!BB13 -> 0 | AK13: ='BIO DATA'!BC13 -> 0 | AL13: ='BIO DATA'!BD13 -> 0 | AM13: ='BIO DATA'!BE13 -> 0 | AN13: ='BIO DATA'!BF13 -> 0 | AO13: ='BIO DATA'!BG13 -> 0 | AP13: ='BIO DATA'!BH13 -> Ikhwanuddin, S.H.I., M.S.I.
... A26: A | B26: 272 | C26: ='BIO DATA'!D26 -> 11153 | D26: ='BIO DATA'!E26 -> 0095371945 | E26: ='BIO DATA'!F26:F56 -> Rafif Attaya Zahran | F26: ='BIO DATA'!M26 -> Laki-laki | G26: ='BIO DATA'!N26 -> Kulon Progo | H26: ='BIO DATA'!O26 -> 39915 | I26: ='BIO DATA'!S26 -> Islam | J26: ='BIO DATA'!J26 -> 1 | K26: ='BIO DATA'!K26 -> 0 | L26: ='BIO DATA'!T26 -> Cabean Bumirejo Lendah Kulon Progo DIY | M26: ='BIO DATA'!V26 -> Bumirejo | N26: ='BIO DATA'!W26 -> Lendah | O26: ='BIO DATA'!X26 -> Kulon Progo | P26: ='BIO DATA'!Y26 -> DI Yogyakarta | Q26: ='BIO DATA'!Z26 -> MTs Mu'allimin Muh. Yogyakarta | R26: ='BIO DATA'!AA26 -> Jl. Letjend. S. Parman No. 68 Yogyakarta | S26: ='BIO DATA'!AB26 -> 0 | T26: ='BIO DATA'!AC26 -> Bayu Rianto Nugroho, SE | ... AG26: ='BIO DATA'!AP26 -> 0 | AH26: ='BIO DATA'!AZ26 -> 0 | AI26: ='BIO DATA'!BA26 -> Islam | AJ26: ='BIO DATA'!BB26 -> 0 | AK26: ='BIO DATA'!BC26 -> 0 | AL26: ='BIO DATA'!BD26 -> 0 | AM26: ='BIO DATA'!BE26 -> 0 | AN26: ='BIO DATA'!BF26 -> 0 | AO26: ='BIO DATA'!BG26 -> 0 | AP26: ='BIO DATA'!BH26 -> Ikhwanuddin, S.H.I., M.S.I.
A27: A | C27: ='BIO DATA'!D27 -> 11156 | D27: ='BIO DATA'!E27 -> 0096837925 | E27: ='BIO DATA'!F27:F57 -> Raihan Fadilah Anwar | F27: ='BIO DATA'!M27 -> Laki-laki | G27: ='BIO DATA'!N27 -> Labuan Bajo | H27: ='BIO DATA'!O27 -> 40021 | I27: ='BIO DATA'!S27 -> Islam | J27: ='BIO DATA'!J27 -> 1 | K27: ='BIO DATA'!K27 -> 0 | L27: ='BIO DATA'!T27 -> Kampung Air , Lingkungan IV Labuan Bajo Komodo Manggarai Barat NTT | M27: ='BIO DATA'!V27 -> Labuan Bajo | N27: ='BIO DATA'!W27 -> Komodo | O27: ='BIO DATA'!X27 -> Manggarai | P27: ='BIO DATA'!Y27 -> Nusa Tenggara Timur | Q27: ='BIO DATA'!Z27 -> MTs Mu'allimin Muh. Yogyakarta | R27: ='BIO DATA'!AA27 -> Jl. Letjend. S. Parman No. 68 Yogyakarta | S27: ='BIO DATA'!AB27 -> 0 | T27: ='BIO DATA'!AC27 -> Anwar | ... AG27: ='BIO DATA'!AP27 -> 0 | AH27: ='BIO DATA'!AZ27 -> 0 | AI27: ='BIO DATA'!BA27 -> Islam | AJ27: ='BIO DATA'!BB27 -> 0 | AK27: ='BIO DATA'!BC27 -> 0 | AL27: ='BIO DATA'!BD27 -> 0 | AM27: ='BIO DATA'!BE27 -> 0 | AN27: ='BIO DATA'!BF27 -> 0 | AO27: ='BIO DATA'!BG27 -> 0 | AP27: ='BIO DATA'!BH27 -> Ikhwanuddin, S.H.I., M.S.I.
A28: A | C28: ='BIO DATA'!D28 -> 11166 | D28: ='BIO DATA'!E28 -> 0082244966 | E28: ='BIO DATA'!F28:F58 -> Ridwan Latief Abimanyu | F28: ='BIO DATA'!M28 -> Laki-laki | G28: ='BIO DATA'!N28 -> Kulon Progo | H28: ='BIO DATA'!O28 -> 39564 | I28: ='BIO DATA'!S28 -> Islam | J28: ='BIO DATA'!J28 -> 2 | K28: ='BIO DATA'!K28 -> 0 | L28: ='BIO DATA'!T28 -> Nusupan Trihanggo Gamping Sleman DIY | M28: ='BIO DATA'!V28 -> Trihanggo | N28: ='BIO DATA'!W28 -> Gamping | O28: ='BIO DATA'!X28 -> Sleman | P28: ='BIO DATA'!Y28 -> DI Yogyakarta | Q28: ='BIO DATA'!Z28 -> MTs Mu'allimin Muh. Yogyakarta | R28: ='BIO DATA'!AA28 -> Jl. Letjend. S. Parman No. 68 Yogyakarta | S28: ='BIO DATA'!AB28 -> 0 | T28: ='BIO DATA'!AC28 -> Agus Sudarmanto | ... AG28: ='BIO DATA'!AP28 -> 0 | AH28: ='BIO DATA'!AZ28 -> 0 | AI28: ='BIO DATA'!BA28 -> Islam | AJ28: ='BIO DATA'!BB28 -> 0 | AK28: ='BIO DATA'!BC28 -> 0 | AL28: ='BIO DATA'!BD28 -> 0 | AM28: ='BIO DATA'!BE28 -> 0 | AN28: ='BIO DATA'!BF28 -> 0 | AO28: ='BIO DATA'!BG28 -> 0 | AP28: ='BIO DATA'!BH28 -> Ikhwanuddin, S.H.I., M.S.I.
A29: A | C29: ='BIO DATA'!D29 -> 11174 | D29: ='BIO DATA'!E29 -> 0088578558 | E29: ='BIO DATA'!F29:F59 -> Sholahudin Al-Ayyubi | F29: ='BIO DATA'!M29 -> Laki-laki | G29: ='BIO DATA'!N29 -> Surabaya | H29: ='BIO DATA'!O29 -> 39703 | I29: ='BIO DATA'!S29 -> Islam | J29: ='BIO DATA'!J29 -> 2 | K29: ='BIO DATA'!K29 -> 2 | L29: ='BIO DATA'!T29 -> Jl. Mulyosari Tengah 7 No 18 Mulyorejo Surabaya Jawa Timur 60112 | M29: ='BIO DATA'!V29 -> Mulyosari Tengah | N29: ='BIO DATA'!W29 -> Mulyorejo | O29: ='BIO DATA'!X29 -> Surabaya | P29: ='BIO DATA'!Y29 -> Jawa Timur | Q29: ='BIO DATA'!Z29 -> MTs Mu'allimin Muh. Yogyakarta | R29: ='BIO DATA'!AA29 -> Jl. Letjend. S. Parman No. 68 Yogyakarta | S29: ='BIO DATA'!AB29 -> 0 | T29: ='BIO DATA'!AC29 -> Rio Muhammad | ... AG29: ='BIO DATA'!AP29 -> 0 | AH29: ='BIO DATA'!AZ29 -> 0 | AI29: ='BIO DATA'!BA29 -> Islam | AJ29: ='BIO DATA'!BB29 -> 0 | AK29: ='BIO DATA'!BC29 -> 0 | AL29: ='BIO DATA'!BD29 -> 0 | AM29: ='BIO DATA'!BE29 -> 0 | AN29: ='BIO DATA'!BF29 -> 0 | AO29: ='BIO DATA'!BG29 -> 0 | AP29: ='BIO DATA'!BH29 -> Ikhwanuddin, S.H.I., M.S.I.
A30: A | C30: ='BIO DATA'!D30 -> 11180 | D30: ='BIO DATA'!E30 -> 0076298289 | E30: ='BIO DATA'!F30:F60 -> Umar Al Faruq | F30: ='BIO DATA'!M30 -> Laki-laki | G30: ='BIO DATA'!N30 -> Sragen | H30: ='BIO DATA'!O30 -> 39445 | I30: ='BIO DATA'!S30 -> Islam | J30: ='BIO DATA'!J30 -> 2 | K30: ='BIO DATA'!K30 -> 0 | L30: ='BIO DATA'!T30 -> Margorejo, Jono, Rt/Rw 07/02, Tanon, Sragen, Jawa tengah | M30: ='BIO DATA'!V30 -> Jono | N30: ='BIO DATA'!W30 -> Tanon | O30: ='BIO DATA'!X30 -> Sragen | P30: ='BIO DATA'!Y30 -> Jawa tengah | Q30: ='BIO DATA'!Z30 -> MTs Mu'allimin Muh. Yogyakarta | R30: ='BIO DATA'!AA30 -> Jl. Letjend. S. Parman No. 68 Yogyakarta | S30: ='BIO DATA'!AB30 -> 0 | T30: ='BIO DATA'!AC30 -> Joko Suratno | ... AG30: ='BIO DATA'!AP30 -> 0 | AH30: ='BIO DATA'!AZ30 -> 0 | AI30: ='BIO DATA'!BA30 -> Islam | AJ30: ='BIO DATA'!BB30 -> 0 | AK30: ='BIO DATA'!BC30 -> 0 | AL30: ='BIO DATA'!BD30 -> 0 | AM30: ='BIO DATA'!BE30 -> 0 | AN30: ='BIO DATA'!BF30 -> 0 | AO30: ='BIO DATA'!BG30 -> 0 | AP30: ='BIO DATA'!BH30 -> Ikhwanuddin, S.H.I., M.S.I.
A31: A | B31: 287 | C31: ='BIO DATA'!D31 -> 11192 | D31: ='BIO DATA'!E31 -> 0089521814 | E31: ='BIO DATA'!F31:F61 -> Zaydan Rafi Mubarak | F31: ='BIO DATA'!M31 -> Laki-laki | G31: ='BIO DATA'!N31 -> Yogyakarta | H31: ='BIO DATA'!O31 -> 39735 | I31: ='BIO DATA'!S31 -> Islam | J31: ='BIO DATA'!J31 -> 1 | K31: ='BIO DATA'!K31 -> 1 | L31: ='BIO DATA'!T31 -> Pakel Baru UH 6/1112 Sorosutan Umbulharjo Yogyakarta 55162 | M31: ='BIO DATA'!V31 -> Sorosutan | N31: ='BIO DATA'!W31 -> Umbulharjo | O31: ='BIO DATA'!X31 -> Kota Yogyakarta | P31: ='BIO DATA'!Y31 -> DI Yogyakarta | Q31: ='BIO DATA'!Z31 -> MTs Mu'allimin Muh. Yogyakarta | R31: ='BIO DATA'!AA31 -> Jl. Letjend. S. Parman No. 68 Yogyakarta | S31: ='BIO DATA'!AB31 -> 0 | T31: ='BIO DATA'!AC31 -> Fikri Hajian Mubarak | ... AG31: ='BIO DATA'!AP31 -> 0 | AH31: ='BIO DATA'!AZ31 -> 0 | AI31: ='BIO DATA'!BA31 -> Islam | AJ31: ='BIO DATA'!BB31 -> 0 | AK31: ='BIO DATA'!BC31 -> 0 | AL31: ='BIO DATA'!BD31 -> 0 | AM31: ='BIO DATA'!BE31 -> 0 | AN31: ='BIO DATA'!BF31 -> 0 | AO31: ='BIO DATA'!BG31 -> 0 | AP31: ='BIO DATA'!BH31 -> Ikhwanuddin, S.H.I., M.S.I.
A32: A | B32: 289 | C32: ='BIO DATA'!D32 -> 11193 | D32: ='BIO DATA'!E32 -> 0098760415 | E32: ='BIO DATA'!F32:F62 -> Zolla Vajjero Amnestya | F32: ='BIO DATA'!M32 -> Laki-laki | G32: ='BIO DATA'!N32 -> Wonosobo | H32: ='BIO DATA'!O32 -> 39849 | I32: ='BIO DATA'!S32 -> Islam | J32: ='BIO DATA'!J32 -> 1 | K32: ='BIO DATA'!K32 -> 2 | L32: ='BIO DATA'!T32 -> Gunung Saren Lor RT 083 Trimurti Srandakan Bantul DIY | M32: ='BIO DATA'!V32 -> Trimurti | N32: ='BIO DATA'!W32 -> Srandakan | O32: ='BIO DATA'!X32 -> Bantul | P32: ='BIO DATA'!Y32 -> DI Yogyakarta | Q32: ='BIO DATA'!Z32 -> MTs Mu'allimin Muh. Yogyakarta | R32: ='BIO DATA'!AA32 -> Jl. Letjend. S. Parman No. 68 Yogyakarta | S32: ='BIO DATA'!AB32 -> 0 | T32: ='BIO DATA'!AC32 -> Purwanta | ... AG32: ='BIO DATA'!AP32 -> zoraphalosa@gmail.com | AH32: ='BIO DATA'!AZ32 -> Purwanta | AI32: ='BIO DATA'!BA32 -> Islam | AJ32: ='BIO DATA'!BB32 -> S1 | AK32: ='BIO DATA'!BC32 -> PNS | AL32: ='BIO DATA'!BD32 -> Gunungsaren lor Rt 83, Trimurti, srandakan, Bantul | AM32: ='BIO DATA'!BE32 -> Rp. 2.000.000,- s/d Rp. 5.000.000,- | AN32: ='BIO DATA'!BF32 -> 085647341724 | AO32: ='BIO DATA'!BG32 -> 0 | AP32: ='BIO DATA'!BH32 -> Ikhwanuddin, S.H.I., M.S.I.
A33: B | B33: 28 | C33: ='BIO DATA'!D33 -> 10888 | D33: ='BIO DATA'!E33 -> 0087340961 | E33: ='BIO DATA'!F33:F63 -> Ahmad Faiz Ramadhiansyah | F33: ='BIO DATA'!M33 -> Laki-laki | G33: ='BIO DATA'!N33 -> Surabaya | H33: ='BIO DATA'!O33 -> 39697 | I33: ='BIO DATA'!S33 -> Islam | J33: ='BIO DATA'!J33 -> 2 | K33: ='BIO DATA'!K33 -> 2 | L33: ='BIO DATA'!T33 -> Jl. Wisma Permai I No. 63 Mulyorejo Surabaya Jawa Timur 60115 | M33: ='BIO DATA'!V33 -> Mulyorejo | N33: ='BIO DATA'!W33 -> Mulyorejo | O33: ='BIO DATA'!X33 -> Surabaya | P33: ='BIO DATA'!Y33 -> Jawa Timur | Q33: ='BIO DATA'!Z33 -> MTs Mu'allimin Muh. Yogyakarta | R33: ='BIO DATA'!AA33 -> Jl. Letjend. S. Parman No. 68 Yogyakarta | S33: ='BIO DATA'!AB33 -> 0 | T33: ='BIO DATA'!AC33 -> Asrul Irawan Bakhtiarsyah | ... AG33: ='BIO DATA'!AP33 -> detti.nur@gmail.com | AH33: ='BIO DATA'!AZ33 -> 0 | AI33: ='BIO DATA'!BA33 -> Islam | AJ33: ='BIO DATA'!BB33 -> 0 | AK33: ='BIO DATA'!BC33 -> 0 | AL33: ='BIO DATA'!BD33 -> 0 | AM33: ='BIO DATA'!BE33 -> 0 | AN33: ='BIO DATA'!BF33 -> 0 | AO33: ='BIO DATA'!BG33 -> 0 | AP33: ='BIO DATA'!BH33 -> Zulfi Jalal Muhsin, S.Pd.
A34: B | B34: 51 | C34: ='BIO DATA'!D34 -> 10903 | D34: ='BIO DATA'!E34 -> 0084723950 | E34: ='BIO DATA'!F34:F64 -> Alfario Futtaqi Hartono | F34: ='BIO DATA'!M34 -> Laki-laki | G34: ='BIO DATA'!N34 -> Salatiga | H34: ='BIO DATA'!O34 -> 39771 | I34: ='BIO DATA'!S34 -> Islam | J34: ='BIO DATA'!J34 -> 1 | K34: ='BIO DATA'!K34 -> 0 | L34: ='BIO DATA'!T34 -> Perumahan Taman Mutiara, Jl. Intan 1, Blok E1, No. 20-21 Tingkir Tengah Tingkir Salatiga Jawa Tengah | M34: ='BIO DATA'!V34 -> Tingkir Tengah | N34: ='BIO DATA'!W34 -> Tingkir | O34: ='BIO DATA'!X34 -> Salatiga | P34: ='BIO DATA'!Y34 -> Jawa Tengah | Q34: ='BIO DATA'!Z34 -> MTs Mu'allimin Muh. Yogyakarta | R34: ='BIO DATA'!AA34 -> Jl. Letjend. S. Parman No. 68 Yogyakarta | S34: ='BIO DATA'!AB34 -> 0 | T34: ='BIO DATA'!AC34 -> Effendi Hartono | ... AG34: ='BIO DATA'!AP34 -> 0 | AH34: ='BIO DATA'!AZ34 -> 0 | AI34: ='BIO DATA'!BA34 -> Islam | AJ34: ='BIO DATA'!BB34 -> 0 | AK34: ='BIO DATA'!BC34 -> 0 | AL34: ='BIO DATA'!BD34 -> 0 | AM34: ='BIO DATA'!BE34 -> 0 | AN34: ='BIO DATA'!BF34 -> 0 | AO34: ='BIO DATA'!BG34 -> 0 | AP34: ='BIO DATA'!BH34 -> Zulfi Jalal Muhsin, S.Pd.
A35: B | B35: 52 | C35: ='BIO DATA'!D35 -> 10904 | D35: ='BIO DATA'!E35 -> 0086954015 | E35: ='BIO DATA'!F35:F65 -> Alfi Khairi Mumtaza | F35: ='BIO DATA'!M35 -> Laki-laki | G35: ='BIO DATA'!N35 -> Muara Badak | H35: ='BIO DATA'!O35 -> 39715 | I35: ='BIO DATA'!S35 -> Islam | J35: ='BIO DATA'!J35 -> 0 | K35: ='BIO DATA'!K35 -> 0 | L35: ='BIO DATA'!T35 -> Gang Rapak Indah Jembayan Loa Kulu Kutai Kartanegara Kalimantan Timur | M35: ='BIO DATA'!V35 -> Jembayan | N35: ='BIO DATA'!W35 -> Loa Kulu | O35: ='BIO DATA'!X35 -> Kutai Kartanegara | P35: ='BIO DATA'!Y35 -> Kalimantan Timur | Q35: ='BIO DATA'!Z35 -> MTs Mu'allimin Muh. Yogyakarta | R35: ='BIO DATA'!AA35 -> Jl. Letjend. S. Parman No. 68 Yogyakarta | S35: ='BIO DATA'!AB35 -> Prestasi Akademik : Peringkat 1 dari kelas I sampai kelas V | T35: ='BIO DATA'!AC35 -> Drs. H. Ihsanul Karim, MM, MH | ... AG35: ='BIO DATA'!AP35 -> dariana24091972@gmail.com | AH35: ='BIO DATA'!AZ35 -> 0 | AI35: ='BIO DATA'!BA35 -> 0 | AJ35: ='BIO DATA'!BB35 -> 0 | AK35: ='BIO DATA'!BC35 -> 0 | AL35: ='BIO DATA'!BD35 -> 0 | AM35: ='BIO DATA'!BE35 -> 0 | AN35: ='BIO DATA'!BF35 -> 0 | AO35: ='BIO DATA'!BG35 -> 0 | AP35: ='BIO DATA'!BH35 -> Zulfi Jalal Muhsin, S.Pd.
A36: B | B36: 66 | C36: ='BIO DATA'!D36 -> 10912 | D36: ='BIO DATA'!E36 -> 0092792362 | E36: ='BIO DATA'!F36:F66 -> Arkan Zumair Hisyam | F36: ='BIO DATA'!M36 -> Laki-laki | G36: ='BIO DATA'!N36 -> Klaten | H36: ='BIO DATA'!O36 -> 39873 | I36: ='BIO DATA'!S36 -> Islam | J36: ='BIO DATA'!J36 -> 1 | K36: ='BIO DATA'!K36 -> 1 | L36: ='BIO DATA'!T36 -> Margomulyo Gergunung Klaten Utara Klaten Jawa Tengah 57434 | M36: ='BIO DATA'!V36 -> Gergunung | N36: ='BIO DATA'!W36 -> Klaten Utara | O36: ='BIO DATA'!X36 -> Klaten | P36: ='BIO DATA'!Y36 -> Jawa Tengah | Q36: ='BIO DATA'!Z36 -> MTs Mu'allimin Muh. Yogyakarta | R36: ='BIO DATA'!AA36 -> Jl. Letjend. S. Parman No. 68 Yogyakarta | S36: ='BIO DATA'!AB36 -> 0 | T36: ='BIO DATA'!AC36 -> Hermawan Yuliyanto | ... AG36: ='BIO DATA'!AP36 -> 0 | AH36: ='BIO DATA'!AZ36 -> 0 | AI36: ='BIO DATA'!BA36 -> Islam | AJ36: ='BIO DATA'!BB36 -> 0 | AK36: ='BIO DATA'!BC36 -> 0 | AL36: ='BIO DATA'!BD36 -> 0 | AM36: ='BIO DATA'!BE36 -> 0 | AN36: ='BIO DATA'!BF36 -> 0 | AO36: ='BIO DATA'!BG36 -> 0 | AP36: ='BIO DATA'!BH36 -> Zulfi Jalal Muhsin, S.Pd.
A37: B | B37: 82 | C37: ='BIO DATA'!D37 -> 10917 | D37: ='BIO DATA'!E37 -> 0092059445 | E37: ='BIO DATA'!F37:F67 -> Aryasatya Kayana Hasyim | F37: ='BIO DATA'!M37 -> Laki-laki | G37: ='BIO DATA'!N37 -> Yogyakarta | H37: ='BIO DATA'!O37 -> 39824 | I37: ='BIO DATA'!S37 -> Islam | J37: ='BIO DATA'!J37 -> 1 | K37: ='BIO DATA'!K37 -> 0 | L37: ='BIO DATA'!T37 -> Jln. Magelang Km 11 Dukuh RT 02 RW 17 Tridadi Sleman DI Yogyakarta | M37: ='BIO DATA'!V37 -> Tridadi | N37: ='BIO DATA'!W37 -> Sleman | O37: ='BIO DATA'!X37 -> Sleman | P37: ='BIO DATA'!Y37 -> DI Yogyakarta | Q37: ='BIO DATA'!Z37 -> MTs Mu'allimin Muh. Yogyakarta | R37: ='BIO DATA'!AA37 -> Jl. Letjend. S. Parman No. 68 Yogyakarta | S37: ='BIO DATA'!AB37 -> 0 | T37: ='BIO DATA'!AC37 -> Wahid Nurhasyim | ... AG37: ='BIO DATA'!AP37 -> 0 | AH37: ='BIO DATA'!AZ37 -> 0 | AI37: ='BIO DATA'!BA37 -> Islam | AJ37: ='BIO DATA'!BB37 -> 0 | AK37: ='BIO DATA'!BC37 -> 0 | AL37: ='BIO DATA'!BD37 -> 0 | AM37: ='BIO DATA'!BE37 -> 0 | AN37: ='BIO DATA'!BF37 -> 0 | AO37: ='BIO DATA'!BG37 -> 0 | AP37: ='BIO DATA'!BH37 -> Zulfi Jalal Muhsin, S.Pd.
